Workbook
Name Excel_BuiltIn_Print_Titles_2: 'IPDM_renda (IPARDES-PR)'!$A$3:$GX$3
Name indice02_07: #REF!

Sheet Dados Gerais Resumo Por Área
A1: Sistema Rodoviário Estadual de 2022 (Pavimentada + Não Pavimentada)
A2: Lotes | B2: Sup. Regional | C2: Área | D2: Ext. (km) | E2: Fator de Tráfego Média TMDA | F2: PIB per capita - R$ [2023] (IBGE 2022) | G2: IDHMédio (IBGE 2022) | H2: IDPM Geral 2022 (Renda/Educação/Saúde) (IPARDES 2022)
A3: 01 | B3: Leste | C3: A01 | D3: 200.62 | E3: =ROUNDUP(SUMIF('Fator Tráfego (DER-PR)'!$AR$6:$AR$1368,B3&" - "&C3,'Fator Tráfego (DER-PR)'!$AN$6:$AN$1368)/SUMIF('Fator Tráfego (DER-PR)'!$AR$6:$AR$1368,B3&" - "&C3,'Fator Tráfego (DER-PR)'!$J$6:$J$1368),0) -> 2926 | F3: =SUMIF('Dados Gerais por Municipio'!$L$3:$L$491,'Dados Gerais Resumo Por Área'!B3&" - "&'Dados Gerais Resumo Por Área'!C3,'Dados Gerais por Municipio'!$E$3:$E$491)/COUNTIF('Dados Gerais por Municipio'!$L$3:$L$491,'Dados Gerais Resumo Por Área'!B3&" - "&'Dados Gerais Resumo Por Área'!C3) -> 43217.723 | G3: =SUMIF('Dados Gerais por Municipio'!$L$3:$L$491,'Dados Gerais Resumo Por Área'!B3&" - "&'Dados Gerais Resumo Por Área'!C3,'Dados Gerais por Municipio'!$F$3:$F$491)/COUNTIF('Dados Gerais por Municipio'!$L$3:$L$491,'Dados Gerais Resumo Por Área'!B3&" - "&'Dados Gerais Resumo Por Área'!C3) -> 0.70225 | H3: =SUMIF('Dados Gerais por Municipio'!$L$3:$L$491,'Dados Gerais Resumo Por Área'!B3&" - "&'Dados Gerais Resumo Por Área'!C3,'Dados Gerais por Municipio'!$G$3:$G$491)/COUNTIF('Dados Gerais por Municipio'!$L$3:$L$491,'Dados Gerais Resumo Por Área'!B3&" - "&'Dados Gerais Resumo Por Área'!C3) -> 0.67216443
A4: 02 | B4: Leste | C4: A02 | D4: 237.45 | E4: =ROUNDUP(SUMIF('Fator Tráfego (DER-PR)'!$AR$6:$AR$1368,B4&" - "&C4,'Fator Tráfego (DER-PR)'!$AN$6:$AN$1368)/SUMIF('Fator Tráfego (DER-PR)'!$AR$6:$AR$1368,B4&" - "&C4,'Fator Tráfego (DER-PR)'!$J$6:$J$1368),0) -> 6166 | F4: =SUMIF('Dados Gerais por Municipio'!$L$3:$L$491,'Dados Gerais Resumo Por Área'!B4&" - "&'Dados Gerais Resumo Por Área'!C4,'Dados Gerais por Municipio'!$E$3:$E$491)/COUNTIF('Dados Gerais por Municipio'!$L$3:$L$491,'Dados Gerais Resumo Por Área'!B4&" - "&'Dados Gerais Resumo Por Área'!C4) -> 45122.401 | G4: =SUMIF('Dados Gerais por Municipio'!$L$3:$L$491,'Dados Gerais Resumo Por Área'!B4&" - "&'Dados Gerais Resumo Por Área'!C4,'Dados Gerais por Municipio'!$F$3:$F$491)/COUNTIF('Dados Gerais por Municipio'!$L$3:$L$491,'Dados Gerais Resumo Por Área'!B4&" - "&'Dados Gerais Resumo Por Área'!C4) -> 0.68486667 | H4: =SUMIF('Dados Gerais por Municipio'!$L$3:$L$491,'Dados Gerais Resumo Por Área'!B4&" - "&'Dados Gerais Resumo Por Área'!C4,'Dados Gerais por Municipio'!$G$3:$G$491)/COUNTIF('Dados Gerais por Municipio'!$L$3:$L$491,'Dados Gerais Resumo Por Área'!B4&" - "&'Dados Gerais Resumo Por Área'!C4) -> 0.70666049
A5: 03 | B5: Leste | C5: A03 | D5: 197.28 | E5: =ROUNDUP(SUMIF('Fator Tráfego (DER-PR)'!$AR$6:$AR$1368,B5&" - "&C5,'Fator Tráfego (DER-PR)'!$AN$6:$AN$1368)/SUMIF('Fator Tráfego (DER-PR)'!$AR$6:$AR$1368,B5&" - "&C5,'Fator Tráfego (DER-PR)'!$J$6:$J$1368),0) -> 4203 | F5: =SUMIF('Dados Gerais por Municipio'!$L$3:$L$491,'Dados Gerais Resumo Por Área'!B5&" - "&'Dados Gerais Resumo Por Área'!C5,'Dados Gerais por Municipio'!$E$3:$E$491)/COUNTIF('Dados Gerais por Municipio'!$L$3:$L$491,'Dados Gerais Resumo Por Área'!B5&" - "&'Dados Gerais Resumo Por Área'!C5) -> 46763.071 | G5: =SUMIF('Dados Gerais por Municipio'!$L$3:$L$491,'Dados Gerais Resumo Por Área'!B5&" - "&'Dados Gerais Resumo Por Área'!C5,'Dados Gerais por Municipio'!$F$3:$F$491)/COUNTIF('Dados Gerais por Municipio'!$L$3:$L$491,'Dados Gerais Resumo Por Área'!B5&" - "&'Dados Gerais Resumo Por Área'!C5) -> 0.69790909 | H5: =SUMIF('Dados Gerais por Municipio'!$L$3:$L$491,'Dados Gerais Resumo Por Área'!B5&" - "&'Dados Gerais Resumo Por Área'!C5,'Dados Gerais por Municipio'!$G$3:$G$491)/COUNTIF('Dados Gerais por Municipio'!$L$3:$L$491,'Dados Gerais Resumo Por Área'!B5&" - "&'Dados Gerais Resumo Por Área'!C5) -> 0.7170576
A6: 04 | B6: Leste | C6: A04 | D6: 255.87 | E6: =ROUNDUP(SUMIF('Fator Tráfego (DER-PR)'!$AR$6:$AR$1368,B6&" - "&C6,'Fator Tráfego (DER-PR)'!$AN$6:$AN$1368)/SUMIF('Fator Tráfego (DER-PR)'!$AR$6:$AR$1368,B6&" - "&C6,'Fator Tráfego (DER-PR)'!$J$6:$J$1368),0) -> 3408 | F6: =SUMIF('Dados Gerais por Municipio'!$L$3:$L$491,'Dados Gerais Resumo Por Área'!B6&" - "&'Dados Gerais Resumo Por Área'!C6,'Dados Gerais por Municipio'!$E$3:$E$491)/COUNTIF('Dados Gerais por Municipio'!$L$3:$L$491,'Dados Gerais Resumo Por Área'!B6&" - "&'Dados Gerais Resumo Por Área'!C6) -> 55353.041 | G6: =SUMIF('Dados Gerais por Municipio'!$L$3:$L$491,'Dados Gerais Resumo Por Área'!B6&" - "&'Dados Gerais Resumo Por Área'!C6,'Dados Gerais por Municipio'!$F$3:$F$491)/COUNTIF('Dados Gerais por Municipio'!$L$3:$L$491,'Dados Gerais Resumo Por Área'!B6&" - "&'Dados Gerais Resumo Por Área'!C6) -> 0.68885714 | H6: =SUMIF('Dados Gerais por Municipio'!$L$3:$L$491,'Dados Gerais Resumo Por Área'!B6&" - "&'Dados Gerais Resumo Por Área'!C6,'Dados Gerais por Municipio'!$G$3:$G$491)/COUNTIF('Dados Gerais por Municipio'!$L$3:$L$491,'Dados Gerais Resumo Por Área'!B6&" - "&'Dados Gerais Resumo Por Área'!C6) -> 0.74339525
A7: 05 | B7: Leste | C7: A05 | D7: 297.7 | E7: =ROUNDUP(SUMIF('Fator Tráfego (DER-PR)'!$AR$6:$AR$1368,B7&" - "&C7,'Fator Tráfego (DER-PR)'!$AN$6:$AN$1368)/SUMIF('Fator Tráfego (DER-PR)'!$AR$6:$AR$1368,B7&" - "&C7,'Fator Tráfego (DER-PR)'!$J$6:$J$1368),0) -> 3447 | F7: =SUMIF('Dados Gerais por Municipio'!$L$3:$L$491,'Dados Gerais Resumo Por Área'!B7&" - "&'Dados Gerais Resumo Por Área'!C7,'Dados Gerais por Municipio'!$E$3:$E$491)/COUNTIF('Dados Gerais por Municipio'!$L$3:$L$491,'Dados Gerais Resumo Por Área'!B7&" - "&'Dados Gerais Resumo Por Área'!C7) -> 47291.82 | G7: =SUMIF('Dados Gerais por Municipio'!$L$3:$L$491,'Dados Gerais Resumo Por Área'!B7&" - "&'Dados Gerais Resumo Por Área'!C7,'Dados Gerais por Municipio'!$F$3:$F$491)/COUNTIF('Dados Gerais por Municipio'!$L$3:$L$491,'Dados Gerais Resumo Por Área'!B7&" - "&'Dados Gerais Resumo Por Área'!C7) -> 0.686625 | H7: =SUMIF('Dados Gerais por Municipio'!$L$3:$L$491,'Dados Gerais Resumo Por Área'!B7&" - "&'Dados Gerais Resumo Por Área'!C7,'Dados Gerais por Municipio'!$G$3:$G$491)/COUNTIF('Dados Gerais por Municipio'!$L$3:$L$491,'Dados Gerais Resumo Por Área'!B7&" - "&'Dados Gerais Resumo Por Área'!C7) -> 0.73063399
A8: 06 | B8: Campos Gerais | C8: A01 | D8: 305.15 | E8: =ROUNDUP(SUMIF('Fator Tráfego (DER-PR)'!$AR$6:$AR$1368,B8&" - "&C8,'Fator Tráfego (DER-PR)'!$AN$6:$AN$1368)/SUMIF('Fator Tráfego (DER-PR)'!$AR$6:$AR$1368,B8&" - "&C8,'Fator Tráfego (DER-PR)'!$J$6:$J$1368),0) -> 2462 | F8: =SUMIF('Dados Gerais por Municipio'!$L$3:$L$491,'Dados Gerais Resumo Por Área'!B8&" - "&'Dados Gerais Resumo Por Área'!C8,'Dados Gerais por Municipio'!$E$3:$E$491)/COUNTIF('Dados Gerais por Municipio'!$L$3:$L$491,'Dados Gerais Resumo Por Área'!B8&" - "&'Dados Gerais Resumo Por Área'!C8) -> 45972.794 | G8: =SUMIF('Dados Gerais por Municipio'!$L$3:$L$491,'Dados Gerais Resumo Por Área'!B8&" - "&'Dados Gerais Resumo Por Área'!C8,'Dados Gerais por Municipio'!$F$3:$F$491)/COUNTIF('Dados Gerais por Municipio'!$L$3:$L$491,'Dados Gerais Resumo Por Área'!B8&" - "&'Dados Gerais Resumo Por Área'!C8) -> 0.6939 | H8: =SUMIF('Dados Gerais por Municipio'!$L$3:$L$491,'Dados Gerais Resumo Por Área'!B8&" - "&'Dados Gerais Resumo Por Área'!C8,'Dados Gerais por Municipio'!$G$3:$G$491)/COUNTIF('Dados Gerais por Municipio'!$L$3:$L$491,'Dados Gerais Resumo Por Área'!B8&" - "&'Dados Gerais Resumo Por Área'!C8) -> 0.74846373
A9: 07 | B9: Campos Gerais | C9: A02 | D9: 287.51 | E9: =ROUNDUP(SUMIF('Fator Tráfego (DER-PR)'!$AR$6:$AR$1368,B9&" - "&C9,'Fator Tráfego (DER-PR)'!$AN$6:$AN$1368)/SUMIF('Fator Tráfego (DER-PR)'!$AR$6:$AR$1368,B9&" - "&C9,'Fator Tráfego (DER-PR)'!$J$6:$J$1368),0) -> 2750 | F9: =SUMIF('Dados Gerais por Municipio'!$L$3:$L$491,'Dados Gerais Resumo Por Área'!B9&" - "&'Dados Gerais Resumo Por Área'!C9,'Dados Gerais por Municipio'!$E$3:$E$491)/COUNTIF('Dados Gerais por Municipio'!$L$3:$L$491,'Dados Gerais Resumo Por Área'!B9&" - "&'Dados Gerais Resumo Por Área'!C9) -> 64643.592 | G9: =SUMIF('Dados Gerais por Municipio'!$L$3:$L$491,'Dados Gerais Resumo Por Área'!B9&" - "&'Dados Gerais Resumo Por Área'!C9,'Dados Gerais por Municipio'!$F$3:$F$491)/COUNTIF('Dados Gerais por Municipio'!$L$3:$L$491,'Dados Gerais Resumo Por Área'!B9&" - "&'Dados Gerais Resumo Por Área'!C9) -> 0.7186 | H9: =SUMIF('Dados Gerais por Municipio'!$L$3:$L$491,'Dados Gerais Resumo Por Área'!B9&" - "&'Dados Gerais Resumo Por Área'!C9,'Dados Gerais por Municipio'!$G$3:$G$491)/COUNTIF('Dados Gerais por Municipio'!$L$3:$L$491,'Dados Gerais Resumo Por Área'!B9&" - "&'Dados Gerais Resumo Por Área'!C9) -> 0.77188989
A10: 08 | B10: Campos Gerais | C10: A03 | D10: 315.48 | E10: =ROUNDUP(SUMIF('Fator Tráfego (DER-PR)'!$AR$6:$AR$1368,B10&" - "&C10,'Fator Tráfego (DER-PR)'!$AN$6:$AN$1368)/SUMIF('Fator Tráfego (DER-PR)'!$AR$6:$AR$1368,B10&" - "&C10,'Fator Tráfego (DER-PR)'!$J$6:$J$1368),0) -> 2547 | F10: =SUMIF('Dados Gerais por Municipio'!$L$3:$L$491,'Dados Gerais Resumo Por Área'!B10&" - "&'Dados Gerais Resumo Por Área'!C10,'Dados Gerais por Municipio'!$E$3:$E$491)/COUNTIF('Dados Gerais por Municipio'!$L$3:$L$491,'Dados Gerais Resumo Por Área'!B10&" - "&'Dados Gerais Resumo Por Área'!C10) -> 46851.221 | G10: =SUMIF('Dados Gerais por Municipio'!$L$3:$L$491,'Dados Gerais Resumo Por Área'!B10&" - "&'Dados Gerais Resumo Por Área'!C10,'Dados Gerais por Municipio'!$F$3:$F$491)/COUNTIF('Dados Gerais por Municipio'!$L$3:$L$491,'Dados Gerais Resumo Por Área'!B10&" - "&'Dados Gerais Resumo Por Área'!C10) -> 0.65177778 | H10: =SUMIF('Dados Gerais por Municipio'!$L$3:$L$491,'Dados Gerais Resumo Por Área'!B10&" - "&'Dados Gerais Resumo Por Área'!C10,'Dados Gerais por Municipio'!$G$3:$G$491)/COUNTIF('Dados Gerais por Municipio'!$L$3:$L$491,'Dados Gerais Resumo Por Área'!B10&" - "&'Dados Gerais Resumo Por Área'!C10) -> 0.7028867
A11: 09 | B11: Campos Gerais | C11: A04 | D11: 290.73 | E11: =ROUNDUP(SUMIF('Fator Tráfego (DER-PR)'!$AR$6:$AR$1368,B11&" - "&C11,'Fator Tráfego (DER-PR)'!$AN$6:$AN$1368)/SUMIF('Fator Tráfego (DER-PR)'!$AR$6:$AR$1368,B11&" - "&C11,'Fator Tráfego (DER-PR)'!$J$6:$J$1368),0) -> 2065 | F11: =SUMIF('Dados Gerais por Municipio'!$L$3:$L$491,'Dados Gerais Resumo Por Área'!B11&" - "&'Dados Gerais Resumo Por Área'!C11,'Dados Gerais por Municipio'!$E$3:$E$491)/COUNTIF('Dados Gerais por Municipio'!$L$3:$L$491,'Dados Gerais Resumo Por Área'!B11&" - "&'Dados Gerais Resumo Por Área'!C11) -> 47141.524 | G11: =SUMIF('Dados Gerais por Municipio'!$L$3:$L$491,'Dados Gerais Resumo Por Área'!B11&" - "&'Dados Gerais Resumo Por Área'!C11,'Dados Gerais por Municipio'!$F$3:$F$491)/COUNTIF('Dados Gerais por Municipio'!$L$3:$L$491,'Dados Gerais Resumo Por Área'!B11&" - "&'Dados Gerais Resumo Por Área'!C11) -> 0.67016667 | H11: =SUMIF('Dados Gerais por Municipio'!$L$3:$L$491,'Dados Gerais Resumo Por Área'!B11&" - "&'Dados Gerais Resumo Por Área'!C11,'Dados Gerais por Municipio'!$G$3:$G$491)/COUNTIF('Dados Gerais por Municipio'!$L$3:$L$491,'Dados Gerais Resumo Por Área'!B11&" - "&'Dados Gerais Resumo Por Área'!C11) -> 0.74957761
A12: 10 | B12: Campos Gerais | C12: A05 | D12: 383.01 | E12: =ROUNDUP(SUMIF('Fator Tráfego (DER-PR)'!$AR$6:$AR$1368,B12&" - "&C12,'Fator Tráfego (DER-PR)'!$AN$6:$AN$1368)/SUMIF('Fator Tráfego (DER-PR)'!$AR$6:$AR$1368,B12&" - "&C12,'Fator Tráfego (DER-PR)'!$J$6:$J$1368),0) -> 3388 | F12: =SUMIF('Dados Gerais por Municipio'!$L$3:$L$491,'Dados Gerais Resumo Por Área'!B12&" - "&'Dados Gerais Resumo Por Área'!C12,'Dados Gerais por Municipio'!$E$3:$E$491)/COUNTIF('Dados Gerais por Municipio'!$L$3:$L$491,'Dados Gerais Resumo Por Área'!B12&" - "&'Dados Gerais Resumo Por Área'!C12) -> 49309.042 | G12: =SUMIF('Dados Gerais por Municipio'!$L$3:$L$491,'Dados Gerais Resumo Por Área'!B12&" - "&'Dados Gerais Resumo Por Área'!C12,'Dados Gerais por Municipio'!$F$3:$F$491)/COUNTIF('Dados Gerais por Municipio'!$L$3:$L$491,'Dados Gerais Resumo Por Área'!B12&" - "&'Dados Gerais Resumo Por Área'!C12) -> 0.65609091 | H12: =SUMIF('Dados Gerais por Municipio'!$L$3:$L$491,'Dados Gerais Resumo Por Área'!B12&" - "&'Dados Gerais Resumo Por Área'!C12,'Dados Gerais por Municipio'!$G$3:$G$491)/COUNTIF('Dados Gerais por Municipio'!$L$3:$L$491,'Dados Gerais Resumo Por Área'!B12&" - "&'Dados Gerais Resumo Por Área'!C12) -> 0.73447934
A13: 11 | B13: Campos Gerais | C13: A06 | D13: 326.22 | E13: =ROUNDUP(SUMIF('Fator Tráfego (DER-PR)'!$AR$6:$AR$1368,B13&" - "&C13,'Fator Tráfego (DER-PR)'!$AN$6:$AN$1368)/SUMIF('Fator Tráfego (DER-PR)'!$AR$6:$AR$1368,B13&" - "&C13,'Fator Tráfego (DER-PR)'!$J$6:$J$1368),0) -> 1839 | F13: =SUMIF('Dados Gerais por Municipio'!$L$3:$L$491,'Dados Gerais Resumo Por Área'!B13&" - "&'Dados Gerais Resumo Por Área'!C13,'Dados Gerais por Municipio'!$E$3:$E$491)/COUNTIF('Dados Gerais por Municipio'!$L$3:$L$491,'Dados Gerais Resumo Por Área'!B13&" - "&'Dados Gerais Resumo Por Área'!C13) -> 38705.772 | G13: =SUMIF('Dados Gerais por Municipio'!$L$3:$L$491,'Dados Gerais Resumo Por Área'!B13&" - "&'Dados Gerais Resumo Por Área'!C13,'Dados Gerais por Municipio'!$F$3:$F$491)/COUNTIF('Dados Gerais por Municipio'!$L$3:$L$491,'Dados Gerais Resumo Por Área'!B13&" - "&'Dados Gerais Resumo Por Área'!C13) -> 0.6509 | H13: =SUMIF('Dados Gerais por Municipio'!$L$3:$L$491,'Dados Gerais Resumo Por Área'!B13&" - "&'Dados Gerais Resumo Por Área'!C13,'Dados Gerais por Municipio'!$G$3:$G$491)/COUNTIF('Dados Gerais por Municipio'!$L$3:$L$491,'Dados Gerais Resumo Por Área'!B13&" - "&'Dados Gerais Resumo Por Área'!C13) -> 0.7007629
A14: 12 | B14: Campos Gerais | C14: A07 | D14: 192.14 | E14: =ROUNDUP(SUMIF('Fator Tráfego (DER-PR)'!$AR$6:$AR$1368,B14&" - "&C14,'Fator Tráfego (DER-PR)'!$AN$6:$AN$1368)/SUMIF('Fator Tráfego (DER-PR)'!$AR$6:$AR$1368,B14&" - "&C14,'Fator Tráfego (DER-PR)'!$J$6:$J$1368),0) -> 2586 | F14: =SUMIF('Dados Gerais por Municipio'!$L$3:$L$491,'Dados Gerais Resumo Por Área'!B14&" - "&'Dados Gerais Resumo Por Área'!C14,'Dados Gerais por Municipio'!$E$3:$E$491)/COUNTIF('Dados Gerais por Municipio'!$L$3:$L$491,'Dados Gerais Resumo Por Área'!B14&" - "&'Dados Gerais Resumo Por Área'!C14) -> 46524.092 | G14: =SUMIF('Dados Gerais por Municipio'!$L$3:$L$491,'Dados Gerais Resumo Por Área'!B14&" - "&'Dados Gerais Resumo Por Área'!C14,'Dados Gerais por Municipio'!$F$3:$F$491)/COUNTIF('Dados Gerais por Municipio'!$L$3:$L$491,'Dados Gerais Resumo Por Área'!B14&" - "&'Dados Gerais Resumo Por Área'!C14) -> 0.6564 | H14: =SUMIF('Dados Gerais por Municipio'!$L$3:$L$491,'Dados Gerais Resumo Por Área'!B14&" - "&'Dados Gerais Resumo Por Área'!C14,'Dados Gerais por Municipio'!$G$3:$G$491)/COUNTIF('Dados Gerais por Municipio'!$L$3:$L$491,'Dados Gerais Resumo Por Área'!B14&" - "&'Dados Gerais Resumo Por Área'!C14) -> 0.72191773
... A42: 40 | B42: Oeste | C42: A08 | D42: 306.38 | E42: =ROUNDUP(SUMIF('Fator Tráfego (DER-PR)'!$AR$6:$AR$1368,B42&" - "&C42,'Fator Tráfego (DER-PR)'!$AN$6:$AN$1368)/SUMIF('Fator Tráfego (DER-PR)'!$AR$6:$AR$1368,B42&" - "&C42,'Fator Tráfego (DER-PR)'!$J$6:$J$1368),0) -> 2294 | F42: =SUMIF('Dados Gerais por Municipio'!$L$3:$L$491,'Dados Gerais Resumo Por Área'!B42&" - "&'Dados Gerais Resumo Por Área'!C42,'Dados Gerais por Municipio'!$E$3:$E$491)/COUNTIF('Dados Gerais por Municipio'!$L$3:$L$491,'Dados Gerais Resumo Por Área'!B42&" - "&'Dados Gerais Resumo Por Área'!C42) -> 66526.306 | G42: =SUMIF('Dados Gerais por Municipio'!$L$3:$L$491,'Dados Gerais Resumo Por Área'!B42&" - "&'Dados Gerais Resumo Por Área'!C42,'Dados Gerais por Municipio'!$F$3:$F$491)/COUNTIF('Dados Gerais por Municipio'!$L$3:$L$491,'Dados Gerais Resumo Por Área'!B42&" - "&'Dados Gerais Resumo Por Área'!C42) -> 0.697 | H42: =SUMIF('Dados Gerais por Municipio'!$L$3:$L$491,'Dados Gerais Resumo Por Área'!B42&" - "&'Dados Gerais Resumo Por Área'!C42,'Dados Gerais por Municipio'!$G$3:$G$491)/COUNTIF('Dados Gerais por Municipio'!$L$3:$L$491,'Dados Gerais Resumo Por Área'!B42&" - "&'Dados Gerais Resumo Por Área'!C42) -> 0.7436744
D43: =SUM(D3:D42) -> 10974.18
B45: Sistema Rodoviário 2022
B46: Ext. Pavimenta + Não Pavimentada
B47: SR | C47: Ext (km) | D47: %
B48: Leste | C48: =SUM(D3:D7) -> 1188.92 | D48: =C48/$C$53 -> 0.10833794
B49: Campos Gerais | C49: =SUM(D8:D14) -> 2100.24 | D49: =C49/$C$53 -> 0.19138013
B50: Norte | C50: =SUM(D15:D24) -> 2280.77 | D50: =C50/$C$53 -> 0.20783056
B51: Noroeste | C51: =SUM(D25:D34) -> 3040.87 | D51: =C51/$C$53 -> 0.27709314
B52: Oeste | C52: =SUM(D35:D42) -> 2363.38 | D52: =C52/$C$53 -> 0.21535823
B53: Total | C53: =SUM(C48:C52) -> 10974.18
B54: Extensão Pavimentada
B55: SR | C55: Ext (km) | D55: %
B56: Leste | C56: =SUM('[1]Adm e Canteiro ADM'!$D$6:$D$10) -> 768.65 | D56: =C56/$C$61 -> 0.079137839
B57: Campos Gerais | C57: =SUM('[1]Adm e Canteiro ADM'!$D$11:$D$17) -> 1686.65 | D57: =C57/$C$61 -> 0.17365229
B58: Norte | C58: =SUM('[1]Adm e Canteiro ADM'!$D$18:$D$27) -> 2034.42 | D58: =C58/$C$61 -> 0.20945762
B59: Noroeste | C59: =SUM('[1]Adm e Canteiro ADM'!$D$28:$D$37) -> 2955.81 | D59: =C59/$C$61 -> 0.3043211
B60: Oeste | C60: =SUM('[1]Adm e Canteiro ADM'!$D$38:$D$45) -> 2267.27 | D60: =C60/$C$61 -> 0.23343114
B61: Total | C61: =SUM(C56:C60) -> 9712.8

Sheet Dados Gerais Resumo PorSR
A1: Fator Tráfego por Sup. Regional
A2: SR | B2: Sup. Regional | C2: Áreas | D2: Ext. (km) | E2: Fator de Tráfego Média TMDA
A3: 1 | B3: Leste | C3: 5 | D3: =SUM('Dados Gerais Resumo Por Área'!D3:D7) -> 1188.92 | E3: =ROUNDUP(SUMIF('Fator Tráfego (DER-PR)'!$AQ$6:$AQ$1368,B3,'Fator Tráfego (DER-PR)'!$AN$6:$AN$1368)/SUMIF('Fator Tráfego (DER-PR)'!$AQ$6:$AQ$1368,B3,'Fator Tráfego (DER-PR)'!$J$6:$J$1368),0) -> 4059
A4: 2 | B4: Campos Gerais | C4: 7 | D4: =SUM('Dados Gerais Resumo Por Área'!D8:D14) -> 2100.24 | E4: =ROUNDUP(SUMIF('Fator Tráfego (DER-PR)'!$AQ$6:$AQ$1368,B4,'Fator Tráfego (DER-PR)'!$AN$6:$AN$1368)/SUMIF('Fator Tráfego (DER-PR)'!$AQ$6:$AQ$1368,B4,'Fator Tráfego (DER-PR)'!$J$6:$J$1368),0) -> 2544
A5: 3 | B5: Norte | C5: 10 | D5: =SUM('Dados Gerais Resumo Por Área'!D15:D24) -> 2280.77 | E5: =ROUNDUP(SUMIF('Fator Tráfego (DER-PR)'!$AQ$6:$AQ$1368,B5,'Fator Tráfego (DER-PR)'!$AN$6:$AN$1368)/SUMIF('Fator Tráfego (DER-PR)'!$AQ$6:$AQ$1368,B5,'Fator Tráfego (DER-PR)'!$J$6:$J$1368),0) -> 2183
A6: 4 | B6: Noroeste | C6: 10 | D6: =SUM('Dados Gerais Resumo Por Área'!D25:D34) -> 3040.87 | E6: =ROUNDUP(SUMIF('Fator Tráfego (DER-PR)'!$AQ$6:$AQ$1368,B6,'Fator Tráfego (DER-PR)'!$AN$6:$AN$1368)/SUMIF('Fator Tráfego (DER-PR)'!$AQ$6:$AQ$1368,B6,'Fator Tráfego (DER-PR)'!$J$6:$J$1368),0) -> 1744
A7: 5 | B7: Oeste | C7: 8 | D7: =SUM('Dados Gerais Resumo Por Área'!D35:D42) -> 2363.38 | E7: =ROUNDUP(SUMIF('Fator Tráfego (DER-PR)'!$AQ$6:$AQ$1368,B7,'Fator Tráfego (DER-PR)'!$AN$6:$AN$1368)/SUMIF('Fator Tráfego (DER-PR)'!$AQ$6:$AQ$1368,B7,'Fator Tráfego (DER-PR)'!$J$6:$J$1368),0) -> 1916
C8: =SUM(C3:C7) -> 40 | D8: =SUM(D3:D7) -> 10974.18
A10: *TMDA - Tráfego Médio Diário Anual
B12: Sistema Rodoviário 2022
B13: Ext. Pavimenta + Não Pavimentada
B14: SR | C14: Ext (km) | D14: %
B15: Leste | C15: =SUM(D3:D3) -> 1188.92 | D15: =C15/$C$20 -> 0.10833794
B16: Campos Gerais | C16: =SUM(D4:D4) -> 2100.24 | D16: =C16/$C$20 -> 0.19138013
B17: Norte | C17: =SUM(D5:D5) -> 2280.77 | D17: =C17/$C$20 -> 0.20783056
B18: Noroeste | C18: =SUM(D6:D6) -> 3040.87 | D18: =C18/$C$20 -> 0.27709314
B19: Oeste | C19: =SUM(D7:D7) -> 2363.38 | D19: =C19/$C$20 -> 0.21535823
B20: Total | C20: =SUM(C15:C19) -> 10974.18
B21: Extensão Pavimentada
B22: SR | C22: Ext (km) | D22: %
B23: Leste | C23: =SUM('[1]Adm e Canteiro ADM'!$D$6:$D$10) -> 768.65 | D23: =C23/$C$28 -> 0.079137839
B24: Campos Gerais | C24: =SUM('[1]Adm e Canteiro ADM'!$D$11:$D$17) -> 1686.65 | D24: =C24/$C$28 -> 0.17365229
B25: Norte | C25: =SUM('[1]Adm e Canteiro ADM'!$D$18:$D$27) -> 2034.42 | D25: =C25/$C$28 -> 0.20945762
B26: Noroeste | C26: =SUM('[1]Adm e Canteiro ADM'!$D$28:$D$37) -> 2955.81 | D26: =C26/$C$28 -> 0.3043211
B27: Oeste | C27: =SUM('[1]Adm e Canteiro ADM'!$D$38:$D$45) -> 2267.27 | D27: =C27/$C$28 -> 0.23343114
B28: Total | C28: =SUM(C23:C27) -> 9712.8

Sheet Dados Gerais por Municipio
A1: LOTE | B1: SUP. REG. | C1: ÁREA | D1: MUNICIPIO | E1: IBGE 2022 | G1: IDPM - Índices Ipardes - 2022
E2: PIB per capita - R$ [2023] | F2: IDHM | G2: IDPM Geral 2022 | H2: IDPM Renda 2022 | I2: IDPM Educação 2022 | J2: IDPM Saúde 2022
A3: LOTE 01 | B3: Leste | C3: A01 | D3: Antonina | E3: =VLOOKUP(D3,'IDHM (IBGE2022)'!$A$4:$N$402,14,FALSE) -> 55368.68 | F3: =VLOOKUP(D3,'IDHM (IBGE2022)'!$A$4:$J$402,10,FALSE) -> 0.687 | G3: =AVERAGE(H3:J3) -> 0.64103441 | H3: =VLOOKUP(D3,'IPDM_renda (IPARDES-PR)'!$A$4:$N$420,14,FALSE) -> 0.47713553 | I3: =VLOOKUP(D3,'IPDM_educação (IPARDES-PR)'!$A$4:$N$420,14,FALSE) -> 0.73349154 | J3: =VLOOKUP(D3,'IPDM_saúde (IPARDES-PR)'!$A$4:$N$466,14,FALSE) -> 0.71247617 | L3: =B3&" - "&C3 -> Leste - A01
A4: LOTE 01 | B4: Leste | C4: A01 | D4: Campina Grande do Sul | E4: =VLOOKUP(D4,'IDHM (IBGE2022)'!$A$4:$N$402,14,FALSE) -> 60047.41 | F4: =VLOOKUP(D4,'IDHM (IBGE2022)'!$A$4:$J$402,10,FALSE) -> 0.718 | G4: =AVERAGE(H4:J4) -> 0.72599707 | H4: =VLOOKUP(D4,'IPDM_renda (IPARDES-PR)'!$A$4:$N$420,14,FALSE) -> 0.5593837 | I4: =VLOOKUP(D4,'IPDM_educação (IPARDES-PR)'!$A$4:$N$420,14,FALSE) -> 0.8948303 | J4: =VLOOKUP(D4,'IPDM_saúde (IPARDES-PR)'!$A$4:$N$466,14,FALSE) -> 0.72377723 | L4: =B4&" - "&C4 -> Leste - A01
A5: LOTE 01 | B5: Leste | C5: A01 | D5: Guaraqueçaba | E5: =VLOOKUP(D5,'IDHM (IBGE2022)'!$A$4:$N$402,14,FALSE) -> 19660.96 | F5: =VLOOKUP(D5,'IDHM (IBGE2022)'!$A$4:$J$402,10,FALSE) -> 0.587 | G5: =AVERAGE(H5:J5) -> 0.57223015 | H5: =VLOOKUP(D5,'IPDM_renda (IPARDES-PR)'!$A$4:$N$420,14,FALSE) -> 0.28092968 | I5: =VLOOKUP(D5,'IPDM_educação (IPARDES-PR)'!$A$4:$N$420,14,FALSE) -> 0.65578528 | J5: =VLOOKUP(D5,'IPDM_saúde (IPARDES-PR)'!$A$4:$N$466,14,FALSE) -> 0.77997548 | L5: =B5&" - "&C5 -> Leste - A01
A6: LOTE 01 | B6: Leste | C6: A01 | D6: Guaratuba | E6: =VLOOKUP(D6,'IDHM (IBGE2022)'!$A$4:$N$402,14,FALSE) -> 29027.37 | F6: =VLOOKUP(D6,'IDHM (IBGE2022)'!$A$4:$J$402,10,FALSE) -> 0.717 | G6: =AVERAGE(H6:J6) -> 0.69331456 | H6: =VLOOKUP(D6,'IPDM_renda (IPARDES-PR)'!$A$4:$N$420,14,FALSE) -> 0.47404357 | I6: =VLOOKUP(D6,'IPDM_educação (IPARDES-PR)'!$A$4:$N$420,14,FALSE) -> 0.87301052 | J6: =VLOOKUP(D6,'IPDM_saúde (IPARDES-PR)'!$A$4:$N$466,14,FALSE) -> 0.73288959 | L6: =B6&" - "&C6 -> Leste - A01
A7: LOTE 01 | B7: Leste | C7: A01 | D7: Matinhos | E7: =VLOOKUP(D7,'IDHM (IBGE2022)'!$A$4:$N$402,14,FALSE) -> 29246.91 | F7: =VLOOKUP(D7,'IDHM (IBGE2022)'!$A$4:$J$402,10,FALSE) -> 0.743 | G7: =AVERAGE(H7:J7) -> 0.66679244 | H7: =VLOOKUP(D7,'IPDM_renda (IPARDES-PR)'!$A$4:$N$420,14,FALSE) -> 0.45236685 | I7: =VLOOKUP(D7,'IPDM_educação (IPARDES-PR)'!$A$4:$N$420,14,FALSE) -> 0.92436497 | J7: =VLOOKUP(D7,'IPDM_saúde (IPARDES-PR)'!$A$4:$N$466,14,FALSE) -> 0.62364549 | L7: =B7&" - "&C7 -> Leste - A01
A8: LOTE 01 | B8: Leste | C8: A01 | D8: Morretes | E8: =VLOOKUP(D8,'IDHM (IBGE2022)'!$A$4:$N$402,14,FALSE) -> 29204.87 | F8: =VLOOKUP(D8,'IDHM (IBGE2022)'!$A$4:$J$402,10,FALSE) -> 0.686 | G8: =AVERAGE(H8:J8) -> 0.60184614 | H8: =VLOOKUP(D8,'IPDM_renda (IPARDES-PR)'!$A$4:$N$420,14,FALSE) -> 0.45956605 | I8: =VLOOKUP(D8,'IPDM_educação (IPARDES-PR)'!$A$4:$N$420,14,FALSE) -> 0.77996942 | J8: =VLOOKUP(D8,'IPDM_saúde (IPARDES-PR)'!$A$4:$N$466,14,FALSE) -> 0.56600296 | L8: =B8&" - "&C8 -> Leste - A01
A9: LOTE 01 | B9: Leste | C9: A01 | D9: Pontal do Paraná | E9: =VLOOKUP(D9,'IDHM (IBGE2022)'!$A$4:$N$402,14,FALSE) -> 26613.26 | F9: =VLOOKUP(D9,'IDHM (IBGE2022)'!$A$4:$J$402,10,FALSE) -> 0.738 | G9: =AVERAGE(H9:J9) -> 0.62137824 | H9: =VLOOKUP(D9,'IPDM_renda (IPARDES-PR)'!$A$4:$N$420,14,FALSE) -> 0.44671276 | I9: =VLOOKUP(D9,'IPDM_educação (IPARDES-PR)'!$A$4:$N$420,14,FALSE) -> 0.87261304 | J9: =VLOOKUP(D9,'IPDM_saúde (IPARDES-PR)'!$A$4:$N$466,14,FALSE) -> 0.5448089 | L9: =B9&" - "&C9 -> Leste - A01
A10: LOTE 01 | B10: Leste | C10: A01 | D10: Quatro Barras | E10: =VLOOKUP(D10,'IDHM (IBGE2022)'!$A$4:$N$402,14,FALSE) -> 96572.32 | F10: =VLOOKUP(D10,'IDHM (IBGE2022)'!$A$4:$J$402,10,FALSE) -> 0.742 | G10: =AVERAGE(H10:J10) -> 0.85472246 | H10: =VLOOKUP(D10,'IPDM_renda (IPARDES-PR)'!$A$4:$N$420,14,FALSE) -> 0.76100353 | I10: =VLOOKUP(D10,'IPDM_educação (IPARDES-PR)'!$A$4:$N$420,14,FALSE) -> 0.91950194 | J10: =VLOOKUP(D10,'IPDM_saúde (IPARDES-PR)'!$A$4:$N$466,14,FALSE) -> 0.8836619 | L10: =B10&" - "&C10 -> Leste - A01
A11: LOTE 02 | B11: Leste | C11: A02 | D11: Almirante Tamandaré | E11: =VLOOKUP(D11,'IDHM (IBGE2022)'!$A$4:$N$402,14,FALSE) -> 18715.79 | F11: =VLOOKUP(D11,'IDHM (IBGE2022)'!$A$4:$J$402,10,FALSE) -> 0.699 | G11: =AVERAGE(H11:J11) -> 0.62592222 | H11: =VLOOKUP(D11,'IPDM_renda (IPARDES-PR)'!$A$4:$N$420,14,FALSE) -> 0.42379101 | I11: =VLOOKUP(D11,'IPDM_educação (IPARDES-PR)'!$A$4:$N$420,14,FALSE) -> 0.65513361 | J11: =VLOOKUP(D11,'IPDM_saúde (IPARDES-PR)'!$A$4:$N$466,14,FALSE) -> 0.79884205 | L11: =B11&" - "&C11 -> Leste - A02
A12: LOTE 02 | B12: Leste | C12: A02 | D12: Bocaiúva do Sul | E12: =VLOOKUP(D12,'IDHM (IBGE2022)'!$A$4:$N$402,14,FALSE) -> 22971.54 | F12: =VLOOKUP(D12,'IDHM (IBGE2022)'!$A$4:$J$402,10,FALSE) -> 0.64 | G12: =AVERAGE(H12:J12) -> 0.6369049 | H12: =VLOOKUP(D12,'IPDM_renda (IPARDES-PR)'!$A$4:$N$420,14,FALSE) -> 0.53650163 | I12: =VLOOKUP(D12,'IPDM_educação (IPARDES-PR)'!$A$4:$N$420,14,FALSE) -> 0.60176329 | J12: =VLOOKUP(D12,'IPDM_saúde (IPARDES-PR)'!$A$4:$N$466,14,FALSE) -> 0.77244979 | L12: =B12&" - "&C12 -> Leste - A02
A13: LOTE 02 | B13: Leste | C13: A02 | D13: Campina Grande do Sul | E13: =VLOOKUP(D13,'IDHM (IBGE2022)'!$A$4:$N$402,14,FALSE) -> 60047.41 | F13: =VLOOKUP(D13,'IDHM (IBGE2022)'!$A$4:$J$402,10,FALSE) -> 0.718 | G13: =AVERAGE(H13:J13) -> 0.72599707 | H13: =VLOOKUP(D13,'IPDM_renda (IPARDES-PR)'!$A$4:$N$420,14,FALSE) -> 0.5593837 | I13: =VLOOKUP(D13,'IPDM_educação (IPARDES-PR)'!$A$4:$N$420,14,FALSE) -> 0.8948303 | J13: =VLOOKUP(D13,'IPDM_saúde (IPARDES-PR)'!$A$4:$N$466,14,FALSE) -> 0.72377723 | L13: =B13&" - "&C13 -> Leste - A02
A14: LOTE 02 | B14: Leste | C14: A02 | D14: Cerro Azul | E14: =VLOOKUP(D14,'IDHM (IBGE2022)'!$A$4:$N$402,14,FALSE) -> 23181.48 | F14: =VLOOKUP(D14,'IDHM (IBGE2022)'!$A$4:$J$402,10,FALSE) -> 0.573 | G14: =AVERAGE(H14:J14) -> 0.62008672 | H14: =VLOOKUP(D14,'IPDM_renda (IPARDES-PR)'!$A$4:$N$420,14,FALSE) -> 0.4151293 | I14: =VLOOKUP(D14,'IPDM_educação (IPARDES-PR)'!$A$4:$N$420,14,FALSE) -> 0.62443495 | J14: =VLOOKUP(D14,'IPDM_saúde (IPARDES-PR)'!$A$4:$N$466,14,FALSE) -> 0.82069592 | L14: =B14&" - "&C14 -> Leste - A02
... A491: LOTE 40 | B491: Oeste | C491: A08 | D491: Vitorino | E491: =VLOOKUP(D491,'IDHM (IBGE2022)'!$A$4:$N$402,14,FALSE) -> 65013.87 | F491: =VLOOKUP(D491,'IDHM (IBGE2022)'!$A$4:$J$402,10,FALSE) -> 0.702 | G491: =AVERAGE(H491:J491) -> 0.71694384 | H491: =VLOOKUP(D491,'IPDM_renda (IPARDES-PR)'!$A$4:$N$420,14,FALSE) -> 0.52482725 | I491: =VLOOKUP(D491,'IPDM_educação (IPARDES-PR)'!$A$4:$N$420,14,FALSE) -> 0.77299839 | J491: =VLOOKUP(D491,'IPDM_saúde (IPARDES-PR)'!$A$4:$N$466,14,FALSE) -> 0.85300587 | L491: =B491&" - "&C491 -> Oeste - A08

Sheet Fator Tráfego (DER-PR)
A2: PLANILHA GERAL (PRs + MUN) | P2: caracaterísticas geométricas
AO4: =ROUNDUP(AN1371/J1371,0) -> 2199
A5: Trecho | H5: DE | I5: PARA | J5: Ext. (km) | K5: Área Gestão | L5: SR | M5: Lotes Conserva | N5: Obs | O5: LOTE | P5: Sit | Q5: Base | R5: Revestimento | S5: Largura | T5: Acostamento | U5: 3ª Faixa | V5: TMDA | W5: 1 | X5: 2 | Y5: 3 | Z5: 4 | AA5: 5 | AE5: 1 | AF5: 2 | AG5: 3 | AH5: 4 | AI5: 5 | AN5: TMDA x Ext. (km)
A6: 082S0090EPR | B6: 082S0090 | C6: 082 | D6: 0090 | E6: 082S | F6: S | G6: 082|0090 | H6: ROSÁRIO DO IVAÍ | I6: ENTR. PR-535 (P/ RIO BRANCO DO IVAÍ) | J6: 18 | K6: A10 | L6: DER SR3 | O6: 22 | P6: PAV | Q6: MH | R6: PMF | S6: 6.2 | T6: 0.5 | U6: 0 | V6: 1080 | W6: 0 | X6: 0 | Y6: 0 | Z6: 18 | AA6: 0 | AB6: =SUM(W6:AA6)-J6 -> 0 | AE6: 0 | AF6: 0 | AG6: 0 | AH6: 18 | AI6: 0 | AJ6: =SUM(AE6:AI6)-J6 -> 0 | AN6: =ROUNDUP(V6*J6,0) -> 19440 | AQ6: Norte | AR6: =AQ6&" - "&K6 -> Norte - A10
A7: 082S0100EPR | B7: 082S0100 | C7: 082 | D7: 0100 | E7: 082S | F7: S | G7: 082|0100 | H7: ENTR. PR-535 (P/ RIO BRANCO DO IVAÍ) | I7: RIBEIRÃO BONITO (A) | J7: 7.53 | K7: A10 | L7: DER SR3 | O7: 22 | P7: PAV | Q7: MH | R7: PMF | S7: 6.2 | T7: 0.5 | U7: 0 | V7: 1080 | W7: 0 | X7: 0 | Y7: 0 | Z7: 7.53 | AA7: 0 | AB7: =SUM(W7:AA7)-J7 -> 0 | AE7: 0 | AF7: 0 | AG7: 0 | AH7: 7.53 | AI7: 0 | AJ7: =SUM(AE7:AI7)-J7 -> 0 | AN7: =ROUNDUP(V7*J7,0) -> 8133 | AQ7: Norte | AR7: =AQ7&" - "&K7 -> Norte - A10
A8: 082M0105MUN | B8: 082M0105 | C8: 082 | D8: 0105 | E8: 082M | F8: M | G8: 082|0105 | H8: RIBEIRÃO BONITO (A) | I8: RIBEIRÃO BONITO (B) | J8: 0.65 | K8: A10 | L8: DER SR3 | O8: 22 | P8: MUN | Q8: MH | R8: PMF | S8: 8.3 | T8: 0 | U8: 0 | V8: 510 | W8: 0 | X8: 0 | Y8: 0 | Z8: 0.65 | AA8: 0 | AB8: =SUM(W8:AA8)-J8 -> 0 | AE8: 0 | AF8: 0 | AG8: 0 | AH8: 0.65 | AI8: 0 | AJ8: =SUM(AE8:AI8)-J8 -> 0 | AN8: =ROUNDUP(V8*J8,0) -> 332 | AQ8: Norte | AR8: =AQ8&" - "&K8 -> Norte - A10
A9: 082S0110EPR | B9: 082S0110 | C9: 082 | D9: 0110 | E9: 082S | F9: S | G9: 082|0110 | H9: RIBEIRÃO BONITO (B) | I9: ENTR. PR-451 (GRANDES RIOS) | J9: 8.12 | K9: A10 | L9: DER SR3 | O9: 22 | P9: PAV | Q9: MH | R9: PMF | S9: 7 | T9: 0.5 | U9: 0 | V9: 1080 | W9: 0 | X9: 0 | Y9: 0 | Z9: 8.12 | AA9: 0 | AB9: =SUM(W9:AA9)-J9 -> 0 | AE9: 0 | AF9: 0 | AG9: 0 | AH9: 8.12 | AI9: 0 | AJ9: =SUM(AE9:AI9)-J9 -> 0 | AN9: =ROUNDUP(V9*J9,0) -> 8770 | AQ9: Norte | AR9: =AQ9&" - "&K9 -> Norte - A10
A10: 082S0150EPR | B10: 082S0150 | C10: 082 | D10: 0150 | E10: 082S | F10: S | G10: 082|0150 | H10: ENTR. PRC-466 (PLACA LUAR) | I10: AC. LUNARDELLI | J10: 10.4 | K10: A07 | L10: DER SR3 | O10: 19 | P10: PAV | Q10: BG | R10: PMF | S10: 7.2 | T10: 1.2 | U10: 0 | V10: 3529 | W10: 0 | X10: 0 | Y10: 0 | Z10: 10.4 | AA10: 0 | AB10: =SUM(W10:AA10)-J10 -> 0 | AE10: 0 | AF10: 0 | AG10: 0 | AH10: 10.4 | AI10: 0 | AJ10: =SUM(AE10:AI10)-J10 -> 0 | AN10: =ROUNDUP(V10*J10,0) -> 36702 | AQ10: Norte | AR10: =AQ10&" - "&K10 -> Norte - A07
A11: 082S0160EPR | B11: 082S0160 | C11: 082 | D11: 0160 | E11: 082S | F11: S | G11: 082|0160 | H11: AC. LUNARDELLI | I11: ENTR. PR-650 (SÃO JOÃO DO IVAÍ) | J11: 14.48 | K11: A07 | L11: DER SR3 | O11: 19 | P11: PAV | Q11: BG | R11: PMF | S11: 7.3 | T11: 1.2 | U11: 0 | V11: 3176 | W11: 0 | X11: 0 | Y11: 0 | Z11: 14.48 | AA11: 0 | AB11: =SUM(W11:AA11)-J11 -> 0 | AE11: 0 | AF11: 0 | AG11: 0 | AH11: 14.48 | AI11: 0 | AJ11: =SUM(AE11:AI11)-J11 -> 0 | AN11: =ROUNDUP(V11*J11,0) -> 45989 | AQ11: Norte | AR11: =AQ11&" - "&K11 -> Norte - A07
A12: 082S0170EPR | B12: 082S0170 | C12: 082 | D12: 0170 | E12: 082S | F12: S | G12: 082|0170 | H12: ENTR. PR-650 (SÃO JOÃO DO IVAÍ) | I12: ENTR. PR-457 (P/ S. PEDRO DO IVAÍ) | J12: 6.46 | K12: A07 | L12: DER SR3 | O12: 19 | P12: PAV | Q12: BG | R12: PMF | S12: 7.2 | T12: 1.2 | U12: 0.4 | V12: 3176 | W12: 0 | X12: 1 | Y12: 0 | Z12: 5.46 | AA12: 0 | AB12: =SUM(W12:AA12)-J12 -> 0 | AE12: 0 | AF12: 1 | AG12: 0 | AH12: 5.46 | AI12: 0 | AJ12: =SUM(AE12:AI12)-J12 -> 0 | AN12: =ROUNDUP(V12*J12,0) -> 20517 | AQ12: Norte | AR12: =AQ12&" - "&K12 -> Norte - A07
A13: 082S0190EPR | B13: 082S0190 | C13: 082 | D13: 0190 | E13: 082S | F13: S | G13: 082|0190 | H13: ENTR. PR-457 (P/ S. PEDRO DO IVAÍ) | I13: ACESSO A LUAR | J13: 6.58 | K13: A07 | L13: DER SR3 | O13: 19 | P13: PAV | Q13: BG | R13: TST | S13: 7.2 | T13: 1.2 | U13: 0 | V13: 2549 | W13: 0 | X13: 1 | Y13: 2 | Z13: 3.58 | AA13: 0 | AB13: =SUM(W13:AA13)-J13 -> 0 | AE13: 0 | AF13: 1 | AG13: 2 | AH13: 3.58 | AI13: 0 | AJ13: =SUM(AE13:AI13)-J13 -> 0 | AN13: =ROUNDUP(V13*J13,0) -> 16773 | AQ13: Norte | AR13: =AQ13&" - "&K13 -> Norte - A07
A14: 082S0195EPR | B14: 082S0195 | C14: 082 | D14: 0195 | E14: 082S | F14: S | G14: 082|0195 | H14: ACESSO A LUAR | I14: RIO CORUMBATAÍ | J14: 5 | K14: A07 | L14: DER SR3 | O14: 19 | P14: PAV | Q14: BG | R14: TST | S14: 7.2 | T14: 1.2 | U14: 0 | V14: 2549 | W14: 0 | X14: 1 | Y14: 0 | Z14: 4 | AA14: 0 | AB14: =SUM(W14:AA14)-J14 -> 0 | AE14: 0 | AF14: 1 | AG14: 0 | AH14: 4 | AI14: 0 | AJ14: =SUM(AE14:AI14)-J14 -> 0 | AN14: =ROUNDUP(V14*J14,0) -> 12745 | AQ14: Norte | AR14: =AQ14&" - "&K14 -> Norte - A07
A15: 082S0200EPR | B15: 082S0200 | C15: 082 | D15: 0200 | E15: 082S | F15: S | G15: 082|0200 | H15: RIO CORUMBATAÍ | I15: ENTR. PRC-369 (FÊNIX) | J15: 2.27 | K15: A02 | L15: DER SR4 | O15: 24 | P15: PAV | Q15: SC | R15: CAUQ | S15: 7 | T15: 2.4 | U15: 0 | V15: 980 | W15: 0 | X15: 0 | Y15: 0 | Z15: 2.27 | AA15: 0 | AB15: =SUM(W15:AA15)-J15 -> 0 | AE15: 0 | AF15: 0 | AG15: 0 | AH15: 2.27 | AI15: 0 | AJ15: =SUM(AE15:AI15)-J15 -> 0 | AN15: =ROUNDUP(V15*J15,0) -> 2225 | AQ15: Noroeste | AR15: =AQ15&" - "&K15 -> Noroeste - A02
A16: 082S0205EPR | B16: 082S0205 | C16: 082 | D16: 0205 | E16: 082S | F16: S | G16: 082|0205 | H16: ENTR. PRC-369 (FÊNIX) | I16: ACESSO A FÊNIX | J16: 0.48 | K16: A02 | L16: DER SR4 | O16: 24 | P16: PAV | Q16: SC | R16: CAUQ | S16: 7 | T16: 2.4 | U16: 0 | V16: 980 | W16: 0 | X16: 0 | Y16: 0 | Z16: 0.48 | AA16: 0 | AB16: =SUM(W16:AA16)-J16 -> 0 | AE16: 0 | AF16: 0 | AG16: 0 | AH16: 0.48 | AI16: 0 | AJ16: =SUM(AE16:AI16)-J16 -> 0 | AN16: =ROUNDUP(V16*J16,0) -> 471 | AQ16: Noroeste | AR16: =AQ16&" - "&K16 -> Noroeste - A02
A17: 082S0210EPR | B17: 082S0210 | C17: 082 | D17: 0210 | E17: 082S | F17: S | G17: 082|0210 | H17: ACESSO A FÊNIX | I17: AC. SECUND. QUINTA DO SOL | J17: 18.35 | K17: A02 | L17: DER SR4 | O17: 24 | P17: PAV | Q17: SC | R17: CAUQ | S17: 7 | T17: 2.4 | U17: 0 | V17: 974 | W17: 0 | X17: 0 | Y17: 0 | Z17: 18.35 | AA17: 0 | AB17: =SUM(W17:AA17)-J17 -> 0 | AE17: 0 | AF17: 0 | AG17: 0 | AH17: 18.35 | AI17: 0 | AJ17: =SUM(AE17:AI17)-J17 -> 0 | AN17: =ROUNDUP(V17*J17,0) -> 17873 | AQ17: Noroeste | AR17: =AQ17&" - "&K17 -> Noroeste - A02
... A50: 082S0460EPR | B50: 082S0460 | C50: 082 | D50: 0460 | E50: 082S | F50: S | G50: 082|0460 | H50: ENTR. PR-485 (ICARAÍMA) (B) | I50: (ICARAÍMA) (C) | J50: 1.72 | K50: A10 | L50: DER SR4 | O50: 32 | P50: PAV | Q50: Solo-solo | R50: CAUQ | S50: 7 | T50: 0.5 | U50: 0 | V50: 420 | W50: 0 | X50: 0 | Y50: 0 | Z50: 1.72 | AA50: 0 | AB50: =SUM(W50:AA50)-J50 -> 0 | AE50: 0 | AF50: 0 | AG50: 0 | AH50: 1.72 | AI50: 0 | AJ50: =SUM(AE50:AI50)-J50 -> 0 | AN50: =ROUNDUP(V50*J50,0) -> 723 | AQ50: Noroeste | AR50: =AQ50&" - "&K50 -> Noroeste - A10
A51: 082S0470EPR | B51: 082S0470 | C51: 082 | D51: 0470 | E51: 082S | F51: S | G51: 082|0470 | H51: (ICARAÍMA) (C) | I51: ENTR. BR-487 (AC. PONTE S/ RIO PARANÁ) | J51: 11.65 | K51: A10 | L51: DER SR4 | P51: PAV | Q51: Solo-solo | R51: CAUQ | S51: 7 | T51: 0.5 | U51: 0 | V51: 420 | W51: 0 | X51: 0 | Y51: 0 | Z51: 11.65 | AA51: 0 | AB51: =SUM(W51:AA51)-J51 -> 0 | AE51: 0 | AF51: 0 | AG51: 0 | AH51: 11.65 | AI51: 0 | AJ51: =SUM(AE51:AI51)-J51 -> 0 | AN51: =ROUNDUP(V51*J51,0) -> 4893 | AQ51: Noroeste | AR51: =AQ51&" - "&K51 -> Noroeste - A10
A52: 090D0010EPR | B52: 090D0010 | C52: 090 | D52: 0010 | E52: 090D | F52: D | G52: 090|0010D | H52: ENTR. PR-418 (CURITIBA) | I52: FINAL PISTA DUPLA | J52: 1.3 | K52: A03 | L52: DER SR1 | O52: 3 | P52: DUP | Q52: BG | R52: CAUQ | S52: 8.2678159 | T52: 0 | U52: 0 | V52: 6995 | W52: 0 | X52: 0 | Y52: 1.3 | Z52: 0 | AA52: 0 | AB52: =SUM(W52:AA52)-J52 -> 0 | AE52: 0 | AF52: 0 | AG52: 1.3 | AH52: 0 | AI52: 0 | AJ52: =SUM(AE52:AI52)-J52 -> 0 | AN52: =ROUNDUP(V52*J52,0) -> 9094 | AQ52: Leste | AR52: =AQ52&" - "&K52 -> Leste - A03
A53: 090E0010EPR | B53: 090E0010 | C53: 090 | D53: 0010 | E53: 090E | F53: E | G53: 090|0010E | H53: ENTR. PR-418 (CURITIBA) | I53: FINAL PISTA DUPLA | J53: 1.3 | K53: A03 | L53: DER SR1 | O53: 3 | P53: DUP | Q53: BG | R53: CAUQ | S53: 8.2678159 | T53: 0 | U53: 0 | V53: 6995 | W53: 0 | X53: 0 | Y53: 1.3 | Z53: 0 | AA53: 0 | AB53: =SUM(W53:AA53)-J53 -> 0 | AE53: 0 | AF53: 0 | AG53: 1.3 | AH53: 0 | AI53: 0 | AJ53: =SUM(AE53:AI53)-J53 -> 0 | AN53: =ROUNDUP(V53*J53,0) -> 9094 | AQ53: Leste | AR53: =AQ53&" - "&K53 -> Leste - A03
A54: 090S0011EPR | B54: 090S0011 | C54: 090 | D54: 0011 | E54: 090S | F54: S | G54: 090|0011 | H54: FINAL PISTA DUPLA | I54: CAMPO MAGRO | J54: 6.7 | K54: A03 | L54: DER SR1 | O54: 3 | P54: PAV | Q54: SE | R54: CAUQ | S54: 8.487403 | T54: 2.5 | U54: 0 | V54: 8953 | W54: 0 | X54: 0 | Y54: 3.7 | Z54: 3 | AA54: 0 | AB54: =SUM(W54:AA54)-J54 -> 0 | AE54: 0 | AF54: 0 | AG54: 3.7 | AH54: 3 | AI54: 0 | AJ54: =SUM(AE54:AI54)-J54 -> 0 | AN54: =ROUNDUP(V54*J54,0) -> 59986 | AQ54: Leste | AR54: =AQ54&" - "&K54 -> Leste - A03
A55: 090S0012EPR | B55: 090S0012 | C55: 090 | D55: 0012 | E55: 090S | F55: S | G55: 090|0012 | H55: CAMPO MAGRO | I55: ENTR. PR-510 (A) (BATEIAS) | J55: 9.54 | K55: A03 | L55: DER SR1 | O55: 3 | P55: PAV | Q55: SE | R55: CAUQ | S55: 8.0376939 | T55: 2.5 | U55: 0 | V55: 1461 | W55: 0 | X55: 0 | Y55: 2 | Z55: 7.54 | AA55: 0 | AB55: =SUM(W55:AA55)-J55 -> 0 | AE55: 0 | AF55: 0 | AG55: 2 | AH55: 7.54 | AI55: 0 | AJ55: =SUM(AE55:AI55)-J55 -> 0 | AN55: =ROUNDUP(V55*J55,0) -> 13938 | AQ55: Leste | AR55: =AQ55&" - "&K55 -> Leste - A03
A56: 090S0014EPR | B56: 090S0014 | C56: 090 | D56: 0014 | E56: 090S | F56: S | G56: 090|0014 | H56: ENTR. PR-510 (A) (BATEIAS) | I56: ENTR. PR-510 (B) / 509(PLAN.) (BATEIAS) | J56: 0.93 | K56: A03 | L56: DER SR1 | O56: 3 | P56: PAV | Q56: BG | R56: CAUQ | S56: 8.5741935 | T56: 2.5 | U56: 0 | V56: 632 | W56: 0 | X56: 0 | Y56: 0 | Z56: 0.93 | AA56: 0 | AB56: =SUM(W56:AA56)-J56 -> 0 | AE56: 0 | AF56: 0 | AG56: 0 | AH56: 0.93 | AI56: 0 | AJ56: =SUM(AE56:AI56)-J56 -> 0 | AN56: =ROUNDUP(V56*J56,0) -> 588 | AQ56: Leste | AR56: =AQ56&" - "&K56 -> Leste - A03
A57: 090S0030EPR | B57: 090S0030 | C57: 090 | D57: 0030 | E57: 090S | F57: S | G57: 090|0030 | H57: ENTR. PR-510 (B)/509(PLAN.) (BATEIAS) | I57: FINAL DO PAVIMENTO (2ª PONTE RIO DO CERNE) | J57: 8.38 | K57: A03 | L57: DER SR1 | O57: 3 | P57: PAV | Q57: BG | R57: CAUQ | S57: 9.3234224 | T57: 1.5 | U57: 1.1 | V57: 1171 | W57: 0 | X57: 0 | Y57: 0 | Z57: 8.38 | AA57: 0 | AB57: =SUM(W57:AA57)-J57 -> 0 | AE57: 0 | AF57: 0 | AG57: 0 | AH57: 8.38 | AI57: 0 | AJ57: =SUM(AE57:AI57)-J57 -> 0 | AN57: =ROUNDUP(V57*J57,0) -> 9813 | AQ57: Leste | AR57: =AQ57&" - "&K57 -> Leste - A03
A58: 090S0075EPR | B58: 090S0075 | C58: 090 | D58: 0075 | E58: 090S | F58: S | G58: 090|0075 | H58: INÍCIO DO PAVIMENTO (ABAPÃ) | I58: ENTR. PR-340 (P/ CASTROLANDA) | J58: 18.83 | K58: A02 | L58: DER SR2 | O58: 7 | P58: PAV | Q58: BG | R58: CAUQ | S58: 7 | T58: 1.5 | U58: 0 | V58: 1812 | W58: 0 | X58: 0 | Y58: 9 | Z58: 9.83 | AA58: 0 | AB58: =SUM(W58:AA58)-J58 -> 0 | AE58: 0 | AF58: 0 | AG58: 9 | AH58: 9.83 | AI58: 0 | AJ58: =SUM(AE58:AI58)-J58 -> 0 | AN58: =ROUNDUP(V58*J58,0) -> 34120 | AQ58: Campos Gerais | AR58: =AQ58&" - "&K58 -> Campos Gerais - A02
A59: 090S0080EPR | B59: 090S0080 | C59: 090 | D59: 0080 | E59: 090S | F59: S | G59: 090|0080 | H59: ENTR. PR-340 (P/ CASTROLANDA) | I59: ENTR. PR-429 Contorno de Castro | J59: 3.07 | K59: A01 | L59: DER SR2 | O59: 6 | P59: PAV | Q59: BG | R59: CAUQ | S59: 7 | T59: 1.5 | U59: 0 | V59: 1812 | W59: 0 | X59: 0 | Y59: 0.07 | Z59: 3 | AA59: 0 | AB59: =SUM(W59:AA59)-J59 -> 0 | AE59: 0 | AF59: 0 | AG59: 0.07 | AH59: 3 | AI59: 0 | AJ59: =SUM(AE59:AI59)-J59 -> 0 | AN59: =ROUNDUP(V59*J59,0) -> 5563 | AQ59: Campos Gerais | AR59: =AQ59&" - "&K59 -> Campos Gerais - A01
A60: 090S0150EPR | B60: 090S0150 | C60: 090 | D60: 0150 | E60: 090S | F60: S | G60: 090|0150 | H60: ENTR. PR-151 (B) (PIRAÍ DO SUL) | I60: ACESSO I PIRAÍ DO SUL. | J60: 0.85 | K60: A01 | L60: DER SR2 | O60: 6 | P60: PAV | Q60: SC | R60: CAUQ | S60: 7.3 | T60: 0 | U60: 0 | V60: 2819 | W60: 0 | X60: 0 | Y60: 0 | Z60: 0.85 | AA60: 0 | AB60: =SUM(W60:AA60)-J60 -> 0 | AE60: 0 | AF60: 0 | AG60: 0 | AH60: 0.85 | AI60: 0 | AJ60: =SUM(AE60:AI60)-J60 -> 0 | AN60: =ROUNDUP(V60*J60,0) -> 2397 | AQ60: Campos Gerais | AR60: =AQ60&" - "&K60 -> Campos Gerais - A01
A61: 090S0153EPR | B61: 090S0153 | C61: 090 | D61: 0153 | E61: 090S | F61: S | G61: 090|0153 | H61: ACESSO I PIRAÍ DO SUL | I61: ACESSO II PIRAÍ DO SUL | J61: 1.97 | K61: A01 | L61: DER SR2 | O61: 6 | P61: PAV | Q61: SC | R61: CAUQ | S61: 7.2 | T61: 0 | U61: 0 | V61: 2819 | W61: 0 | X61: 0 | Y61: 0 | Z61: 1.97 | AA61: 0 | AB61: =SUM(W61:AA61)-J61 -> 0 | AE61: 0 | AF61: 0 | AG61: 0 | AH61: 1.97 | AI61: 0 | AJ61: =SUM(AE61:AI61)-J61 -> 0 | AN61: =ROUNDUP(V61*J61,0) -> 5554 | AQ61: Campos Gerais | AR61: =AQ61&" - "&K61 -> Campos Gerais - A01
A62: 090S0156EPR | B62: 090S0156 | C62: 090 | D62: 0156 | E62: 090S | F62: S | G62: 090|0156 | H62: ACESSO II PIRAÍ DO SUL | I62: FIM TRECHO OFERTADO | J62: 22.2 | K62: A01 | L62: DER SR2 | O62: 6 | P62: PAV | Q62: SC | R62: CAUQ | S62: 7.3 | T62: 0 | U62: 0 | V62: 2404 | W62: 0 | X62: 0 | Y62: 6 | Z62: 16.2 | AA62: 0 | AB62: =SUM(W62:AA62)-J62 -> 0 | AE62: 0 | AF62: 0 | AG62: 6 | AH62: 16.2 | AI62: 0 | AJ62: =SUM(AE62:AI62)-J62 -> 0 | AN62: =ROUNDUP(V62*J62,0) -> 53369 | AQ62: Campos Gerais | AR62: =AQ62&" - "&K62 -> Campos Gerais - A01
A63: 090S0160EPR | B63: 090S0160 | C63: 090 | D63: 0160 | E63: 090S | F63: S | G63: 090|0160 | H63: FIM TRECHO OFERTADO | I63: ENTR. PR-239 (A) (P/ ARAPOTI) | J63: 15.74 | K63: A01 | L63: DER SR2 | O63: 6 | P63: PAV | Q63: BG | R63: CAUQ | S63: 7 | T63: 1.5 | U63: 1 | V63: 2819 | W63: 0 | X63: 0 | Y63: 4 | Z63: 11.74 | AA63: 0 | AB63: =SUM(W63:AA63)-J63 -> 0 | AE63: 0 | AF63: 0 | AG63: 4 | AH63: 11.74 | AI63: 0 | AJ63: =SUM(AE63:AI63)-J63 -> 0 | AN63: =ROUNDUP(V63*J63,0) -> 44372 | AQ63: Campos Gerais | AR63: =AQ63&" - "&K63 -> Campos Gerais - A01
... A66: 090S0200EPR | B66: 090S0200 | C66: 090 | D66: 0200 | E66: 090S | F66: S | G66: 090|0200 | H66: ENTR. PR-239(B)(PLAN.) (VENTANIA) | I66: ENTR. PRC-153 (P/ IBAITI)/BR-153 (P/ TIBAGI) | J66: 4.87 | K66: A01 | L66: DER SR2 | O66: 6 | P66: PAV | Q66: BG | R66: CAUQ | S66: 7 | T66: 1.5 | U66: 0 | V66: 849 | W66: 0 | X66: 0 | Y66: 1 | Z66: 3.87 | AA66: 0 | AB66: =SUM(W66:AA66)-J66 -> 0 | AE66: 0 | AF66: 0 | AG66: 1 | AH66: 3.87 | AI66: 0 | AJ66: =SUM(AE66:AI66)-J66 -> 0 | AN66: =ROUNDUP(V66*J66,0) -> 4135 | AQ66: Campos Gerais | AR66: =AQ66&" - "&K66 -> Campos Gerais - A01
A67: 090S0210EPR | B67: 090S0210 | C67: 090 | D67: 0210 | E67: 090S | F67: S | G67: 090|0210 | H67: ENTR. PRC-153 (P/ IBAITI) / ENTR. BR-153 (P/ TIBAGI) | I67: ACESSO À BARRO PRETO | J67: 12.25 | K67: A08 | L67: DER SR3 | O67: 20 | P67: PAV | Q67: BG | R67: CAUQ | S67: 7 | T67: 1.5 | U67: 0 | V67: 1744 | W67: 0 | X67: 0 | Y67: 1 | Z67: 11.25 | AA67: 0 | AB67: =SUM(W67:AA67)-J67 -> 0 | AE67: 0 | AF67: 0 | AG67: 1 | AH67: 11.25 | AI67: 0 | AJ67: =SUM(AE67:AI67)-J67 -> 0 | AN67: =ROUNDUP(V67*J67,0) -> 21364 | AQ67: Norte | AR67: =AQ67&" - "&K67 -> Norte - A08
A68: 090S0215EPR | B68: 090S0215 | C68: 090 | D68: 0215 | E68: 090S | F68: S | G68: 090|0215 | H68: ACESSO À BARRO PRETO | I68: ALECRIM | J68: 18.81 | K68: A08 | L68: DER SR3 | O68: 20 | P68: PAV | Q68: BG | R68: CAUQ | S68: 7 | T68: 1.5 | U68: 0 | V68: 1351 | W68: 0 | X68: 0 | Y68: 2 | Z68: 16.81 | AA68: 0 | AB68: =SUM(W68:AA68)-J68 -> 0 | AE68: 0 | AF68: 0 | AG68: 2 | AH68: 16.81 | AI68: 0 | AJ68: =SUM(AE68:AI68)-J68 -> 0 | AN68: =ROUNDUP(V68*J68,0) -> 25413 | AQ68: Norte | AR68: =AQ68&" - "&K68 -> Norte - A08
A69: 090S0220EPR | B69: 090S0220 | C69: 090 | D69: 0220 | E69: 090S | F69: S | G69: 090|0220 | H69: ALECRIM | I69: ENTR. PR-160 (A) (CURIÚVA) | J69: 6.09 | K69: A08 | L69: DER SR3 | O69: 20 | P69: PAV | Q69: BG | R69: CAUQ | S69: 7 | T69: 1.5 | U69: 0 | V69: 1873 | W69: 0 | X69: 0 | Y69: 0 | Z69: 6.09 | AA69: 0 | AB69: =SUM(W69:AA69)-J69 -> 0 | AE69: 0 | AF69: 0 | AG69: 0 | AH69: 6.09 | AI69: 0 | AJ69: =SUM(AE69:AI69)-J69 -> 0 | AN69: =ROUNDUP(V69*J69,0) -> 11407 | AQ69: Norte | AR69: =AQ69&" - "&K69 -> Norte - A08
A70: 090S0230EPR | B70: 090S0230 | C70: 090 | D70: 0230 | E70: 090S | F70: S | G70: 090|0230 | H70: ENTR. PR-160(A) (CURIÚVA) | I70: ENTR. PR-160(B) (CURIÚVA) | J70: 2.73 | K70: A08 | L70: DER SR3 | O70: 20 | P70: PAV | Q70: BG | R70: CAUQ | S70: 7 | T70: 1.5 | U70: 1.7 | V70: 3722 | W70: 0 | X70: 0 | Y70: 1 | Z70: 1.73 | AA70: 0 | AB70: =SUM(W70:AA70)-J70 -> 0 | AE70: 0 | AF70: 0 | AG70: 1 | AH70: 1.73 | AI70: 0 | AJ70: =SUM(AE70:AI70)-J70 -> 0 | AN70: =ROUNDUP(V70*J70,0) -> 10162 | AQ70: Norte | AR70: =AQ70&" - "&K70 -> Norte - A08
A71: 090S0250EPR | B71: 090S0250 | C71: 090 | D71: 0250 | E71: 090S | F71: S | G71: 090|0250 | H71: ENTR. PR-160(B) (CURIÚVA) | I71: ENTR. BR-272(PLAN.) AC. A SAPOPEMA | J71: 18.86 | K71: A08 | L71: DER SR3 | O71: 20 | P71: PAV | Q71: BG | R71: CAUQ | S71: 6.6 | T71: 1.5 | U71: 2.9 | V71: 2276 | W71: 0 | X71: 0 | Y71: 0 | Z71: 18.86 | AA71: 0 | AB71: =SUM(W71:AA71)-J71 -> 0 | AE71: 0 | AF71: 0 | AG71: 0 | AH71: 18.86 | AI71: 0 | AJ71: =SUM(AE71:AI71)-J71 -> 0 | AN71: =ROUNDUP(V71*J71,0) -> 42926 | AQ71: Norte | AR71: =AQ71&" - "&K71 -> Norte - A08
A72: 090S0270EPR | B72: 090S0270 | C72: 090 | D72: 0270 | E72: 090S | F72: S | G72: 090|0270 | H72: ENTR. BR-272(PLAN.) AC. A SAPOPEMA | I72: AC. SÃO JERÔNIMO DA SERRA | J72: 32.57 | K72: A04 | L72: DER SR3 | O72: 16 | P72: PAV | Q72: BG | R72: CAUQ | S72: 6.6 | T72: 1.5 | U72: 5.9 | V72: 1156 | W72: 0 | X72: 0 | Y72: 6 | Z72: 26.57 | AA72: 0 | AB72: =SUM(W72:AA72)-J72 -> 0 | AE72: 0 | AF72: 0 | AG72: 6 | AH72: 26.57 | AI72: 0 | AJ72: =SUM(AE72:AI72)-J72 -> 0 | AN72: =ROUNDUP(V72*J72,0) -> 37651 | AQ72: Norte | AR72: =AQ72&" - "&K72 -> Norte - A04
A73: 090S0290EPR | B73: 090S0290 | C73: 090 | D73: 0290 | E73: 090S | F73: S | G73: 090|0290 | H73: AC. SÃO JERÔNIMO DA SERRA | I73: ENTR. ROD. MUN. P/ CONGONHINHAS (NÃO PAV.) | J73: 0.95 | K73: A04 | L73: DER SR3 | O73: 16 | P73: PAV | Q73: BG | R73: CAUQ | S73: 7.2 | T73: 2.5 | U73: 0 | V73: 1049 | W73: 0 | X73: 0 | Y73: 0 | Z73: 0.95 | AA73: 0 | AB73: =SUM(W73:AA73)-J73 -> 0 | AE73: 0 | AF73: 0 | AG73: 0 | AH73: 0.95 | AI73: 0 | AJ73: =SUM(AE73:AI73)-J73 -> 0 | AN73: =ROUNDUP(V73*J73,0) -> 997 | AQ73: Norte | AR73: =AQ73&" - "&K73 -> Norte - A04
A74: 090S0295EPR | B74: 090S0295 | C74: 090 | D74: 0295 | E74: 090S | F74: S | G74: 090|0295 | H74: ENTR. ROD. MUN. P/ CONGONHINHAS (NÃO PAV.) | I74: AC. NOVA STA. BÁRBARA | J74: 14.09 | K74: A04 | L74: DER SR3 | O74: 16 | P74: PAV | Q74: BG | R74: CAUQ | S74: 7.2 | T74: 2.5 | U74: 0 | V74: 1049 | W74: 0 | X74: 0 | Y74: 0 | Z74: 14.09 | AA74: 0 | AB74: =SUM(W74:AA74)-J74 -> 0 | AE74: 0 | AF74: 0 | AG74: 0 | AH74: 14.09 | AI74: 0 | AJ74: =SUM(AE74:AI74)-J74 -> 0 | AN74: =ROUNDUP(V74*J74,0) -> 14781 | AQ74: Norte | AR74: =AQ74&" - "&K74 -> Norte - A04
A75: 090S0300EPR | B75: 090S0300 | C75: 090 | D75: 0300 | E75: 090S | F75: S | G75: 090|0300 | H75: AC. NOVA STA. BÁRBARA | I75: AC. SANTA CECÍLIA DO PAVÃO | J75: 8.61 | K75: A04 | L75: DER SR3 | O75: 16 | P75: PAV | Q75: BG | R75: CAUQ | S75: 7.2 | T75: 2.5 | U75: 0 | V75: 1049 | W75: 0 | X75: 0 | Y75: 0 | Z75: 8.61 | AA75: 0 | AB75: =SUM(W75:AA75)-J75 -> 0 | AE75: 0 | AF75: 0 | AG75: 0 | AH75: 8.61 | AI75: 0 | AJ75: =SUM(AE75:AI75)-J75 -> 0 | AN75: =ROUNDUP(V75*J75,0) -> 9032 | AQ75: Norte | AR75: =AQ75&" - "&K75 -> Norte - A04
A76: 090S0310EPR | B76: 090S0310 | C76: 090 | D76: 0310 | E76: 090S | F76: S | G76: 090|0310 | H76: AC. SANTA CECÍLIA DO PAVÃO | I76: AC. SECUND. STA. CECÍLIA DO PAVÃO | J76: 0.85 | K76: A04 | L76: DER SR3 | O76: 16 | P76: PAV | Q76: BG | R76: CAUQ | S76: 7.2 | T76: 2.5 | U76: 0 | V76: 4243 | W76: 0 | X76: 0 | Y76: 0.85 | Z76: 0 | AA76: 0 | AB76: =SUM(W76:AA76)-J76 -> 0 | AE76: 0 | AF76: 0 | AG76: 0.85 | AH76: 0 | AI76: 0 | AJ76: =SUM(AE76:AI76)-J76 -> 0 | AN76: =ROUNDUP(V76*J76,0) -> 3607 | AQ76: Norte | AR76: =AQ76&" - "&K76 -> Norte - A04
...

Sheet IDHM (IBGE2022)
A1: Paraná | Todos os Municípios (IBGE 2022)
A3: Município [-] | B3: Código [-] | C3: Gentílico [-] | D3: Prefeito [2025] | E3: Área Territorial - km² [2025] | F3: População no último censo - pessoas [2022] | G3: Densidade demográfica - hab/km² [2022] | H3: População estimada - pessoas [2025] | I3: Escolarização <span>6 a 14 anos</span> - % [2022] | J3: IDHM <span>Índice de desenvolvimento humano municipal</span> [2010] | K3: Mortalidade infantil - óbitos por mil nascidos vivos [2023] | L3: Total de receitas brutas realizadas - R$ [2023] | M3: Total de despesas brutas empenhadas - R$ [2023] | N3: PIB per capita - R$ [2023]
A4: Abatiá | B4: 4100103 | C4: abatiense | D4: SONIA APARECIDA DE SOUZA CHAVES | E4: 227.923 | F4: 7241 | G4: 31.66 | H4: 7233 | I4: 94.88 | J4: 0.687 | K4: - | L4: 48184402 | M4: 40393404 | N4: 41039.39
A5: Adrianópolis | B5: 4100202 | C5: adrianopolitano ou adrianopolense | D5: VANDIR DE OLIVEIRA ROSA | E5: 1343.898 | F5: 6256 | G5: 4.64 | H5: 6319 | I5: 99.64 | J5: 0.667 | K5: - | L5: 65885672 | M5: 60528117 | N5: 74669
A6: Agudos do Sul | B6: 4100301 | C6: agudense-do-sul ou agudense | D6: GENEZIO GONÇALVES DA LUZ | E6: 191.336 | F6: 10233 | G6: 53.22 | H6: 10770 | I6: 98.51 | J6: 0.66 | K6: 29.85 | L6: 56439846 | M6: 48989316 | N6: 27302.69
A7: Almirante Tamandaré | B7: 4100400 | C7: tamandareense | D7: CAMILO DANIEL LOVATO | E7: 193.736 | F7: 119825 | G7: 616.93 | H7: 125861 | I7: 98.36 | J7: 0.699 | K7: 6.57 | L7: 4.6981431e+08 | M7: 4.3286764e+08 | N7: 18715.79
A8: Altamira do Paraná | B8: 4100459 | C8: altamirense | D8: ELZA APARECIDA DA SILVA | E8: 386.952 | F8: 3590 | G8: 9.28 | H8: 3496 | I8: 99.6 | J8: 0.667 | K8: 21.28 | L8: 46198534 | M8: 43168730 | N8: 32175.22
A9: Altônia | B9: 4100509 | C9: altoniano | D9: DIEGO JARDIM PERGO | E9: 663.955 | F9: 18742 | G9: 28.33 | H9: 18634 | I9: 98.08 | J9: 0.721 | K9: 4.9 | L9: 1.2844817e+08 | M9: 1.2452387e+08 | N9: 29153.82
A10: Alto Paraná | B10: 4100608 | C10: alto-paranaense | D10: CLAUDEMIR JOIA PEREIRA | E10: 409.014 | F10: 13909 | G10: 34.11 | H10: 14183 | I10: 99.69 | J10: 0.696 | K10: 24.84 | L10: 98195545 | M10: 97629840 | N10: 40453.42
A11: Alto Piquiri | B11: 4100707 | C11: alto-piquirense | D11: GIOVANE MENDES DE CARVALHO | E11: 448.373 | F11: 9727 | G11: 21.73 | H11: 9771 | I11: 99.04 | J11: 0.676 | K11: 16 | L11: 72062780 | M11: 64639205 | N11: 50230.67
A12: Alvorada do Sul | B12: 4100806 | C12: alvoradense-do-sul | D12: MARCOS ANTONIO GASPARELLI | E12: 424.25 | F12: 10326 | G12: 24.34 | H12: 10481 | I12: 99.3 | J12: 0.708 | K12: 10.53 | L12: 98949999 | M12: 98055610 | N12: 42266.4
A13: Amaporã | B13: 4100905 | C13: amaporense | D13: MARCOS MARIN | E13: 384.91 | F13: 4762 | G13: 12.38 | H13: 4688 | I13: 97.91 | J13: 0.669 | K13: - | L13: 58267630 | M13: 51115529 | N13: 34418.01
A14: Ampére | B14: 4101002 | C14: amperense | D14: DOUGLAS DIEMS MOROCKOSKI POTRICH | E14: 297.174 | F14: 19620 | G14: 65.76 | H14: 20337 | I14: 94.47 | J14: 0.709 | K14: 18.12 | L14: 1.3446431e+08 | M14: 1.2172678e+08 | N14: 51028.26
A15: Anahy | B15: 4101051 | C15: anaiense | D15: ARILSON BATISTA DE SOUZA | E15: 104.09 | F15: 2918 | G15: 28.36 | H15: 2971 | I15: 98.9 | J15: 0.695 | K15: 96.77 | L15: 42860517 | M15: 38037549 | N15: 42605.49
A16: Andirá | B16: 4101101 | C16: andiraense | D16: EDNYRA APARECIDA SANCHES BUENO DE GODOY FERREIRA | E16: 234.635 | F16: 19878 | G16: 84.25 | H16: 19989 | I16: 99.54 | J16: 0.725 | K16: 9.17 | L16: 1.4074397e+08 | M16: 1.4062558e+08 | N16: 43322.9
A17: Ângulo | B17: 4101150 | C17: angulense | D17: ALEXANDRE DE SOUSA PROFETA | E17: 106.021 | F17: 3235 | G17: 30.51 | H17: 3357 | I17: 100 | J17: 0.721 | K17: 25.64 | L17: 48566440 | M17: 48971722 | N17: 55572.79
A18: Antonina | B18: 4101200 | C18: antoninense | D18: ROZANE MARISTELA BENEDETTI OSAKI | E18: 890.065 | F18: 18091 | G18: 20.29 | H18: 18140 | I18: 99.12 | J18: 0.687 | K18: 20.62 | L18: 1.5878553e+08 | M18: 1.5102849e+08 | N18: 55368.68
A19: Antônio Olinto | B19: 4101309 | C19: antoniolintense | D19: FABIO STANISZEWSKI MACHIAVELLI | E19: 463.694 | F19: 7018 | G19: 14.94 | H19: 7048 | I19: 99.59 | J19: 0.656 | K19: 14.49 | L19: 50575449 | M19: 49357482 | N19: 40269.4
A20: Apucarana | B20: 4101408 | C20: apucaranense | D20: RODOLFO MOTA DA SILVA | E20: 556.771 | F20: 130134 | G20: 233.64 | H20: 134910 | I20: 99.57 | J20: 0.748 | K20: 9.68 | L20: 6.8756598e+08 | M20: 652889778 | N20: 37146.42
A21: Arapongas | B21: 4101507 | C21: araponguense | D21: RAFAEL FELIPE CITA | E21: 383.37 | F21: 119138 | G21: 311.7 | H21: 124838 | I21: 96.34 | J21: 0.748 | K21: 11.5 | L21: 7.7087305e+08 | M21: 6.6899856e+08 | N21: 47973.54
A22: Arapoti | B22: 4101606 | C22: arapotiense | D22: IRANI JOSE BARROS | E22: 1363.843 | F22: 25777 | G22: 18.98 | H22: 26325 | I22: 99.38 | J22: 0.723 | K22: 19.83 | L22: 1.9017142e+08 | M22: 1.6137375e+08 | N22: 63347.91
A23: Arapuã | B23: 4101655 | C23: arapuense | D23: MANOEL SALVADOR | E23: 217.599 | F23: 3527 | G23: 16.23 | H23: 3573 | I23: 100 | J23: 0.676 | K23: 23.81 | L23: 43140389 | M23: 37505508 | N23: 43743.99
A24: Araruna | B24: 4101705 | C24: ararunense | D24: GUSTAVO FRANÇA DOS SANTOS | E24: 492.521 | F24: 14485 | G24: 29.37 | H24: 14894 | I24: 99.36 | J24: 0.704 | K24: 17.65 | L24: 1.016425e+08 | M24: 89235336 | N24: 43548.25
A25: Araucária | B25: 4101804 | C25: araucariano | D25: LUIZ GUSTAVO BOTOGOSKI | E25: 469.549 | F25: 151666 | G25: 323.22 | H25: 162247 | I25: 99.26 | J25: 0.74 | K25: 9.46 | L25: 2.0188287e+09 | M25: 1.7655351e+09 | N25: 224671.66
A26: Ariranha do Ivaí | B26: 4101853 | C26: ariranhense do ivaí | D26: THIAGO EPIFANIO DA SILVA | E26: 236.039 | F26: 2329 | G26: 9.95 | H26: 2351 | I26: 100 | J26: 0.67 | K26: 35.71 | L26: 42855937 | M26: 38805906 | N26: 62246.84
A27: Assaí | B27: 4101903 | C27: assaiense | D27: MICHEL ANGELO BOMTEMPO | E27: 440.347 | F27: 13797 | G27: 31.33 | H27: 13477 | I27: 97.56 | J27: 0.728 | K27: - | L27: 1.0668729e+08 | M27: 93803568 | N27: 46183.5
A28: Assis Chateaubriand | B28: 4102000 | C28: assis-chateaubriense | D28: MARCEL HENRIQUE MICHELETTO | E28: 980.816 | F28: 36808 | G28: 37.53 | H28: 38357 | I28: 99.74 | J28: 0.729 | K28: 13.73 | L28: 2.6137416e+08 | M28: 2.2922134e+08 | N28: 55252.41
A29: Astorga | B29: 4102109 | C29: astorgano | D29: SUZIE APARECIDA PUCILLO ZANATTA | E29: 435.21 | F29: 25475 | G29: 58.59 | H29: 26203 | I29: 98.28 | J29: 0.747 | K29: 17.01 | L29: 1.828221e+08 | M29: 1.7336791e+08 | N29: 45723.88
A30: Atalaia | B30: 4102208 | C30: atalaiense | D30: CARLOS EDUARDO ARMELIN MARIANI | E30: 137.075 | F30: 3980 | G30: 28.91 | H30: 4046 | I30: 98.9 | J30: 0.736 | K30: 32.26 | L30: 50133856 | M30: 45344327 | N30: 64007.95
A31: Balsa Nova | B31: 4102307 | C31: balsa-novense | D31: CLEVER APARECIDO IAVOLSKI POLETTO | E31: 347.588 | F31: 13395 | G31: 38.39 | H31: 13867 | I31: 99.25 | J31: 0.696 | K31: 6.54 | L31: 1.170218e+08 | M31: 1.1562185e+08 | N31: 97201.65
A32: Bandeirantes | B32: 4102406 | C32: bandeirantense | D32: JAELSON RAMALHO MATTA | E32: 445.192 | F32: 31273 | G32: 70.25 | H32: 31747 | I32: 99.78 | J32: 0.727 | K32: 2.8 | L32: 1.6204367e+08 | M32: 1.4577426e+08 | N32: 43559.41
A33: Barbosa Ferraz | B33: 4102505 | C33: barbosense | D33: CARLOS ROSA ALVES | E33: 536.101 | F33: 10795 | G33: 20.04 | H33: 10580 | I33: 97.97 | J33: 0.696 | K33: 16.26 | L33: 75370246 | M33: 72347928 | N33: 31695.71
A34: Barracão | B34: 4102604 | C34: barraconense | D34: JORGE LUIZ SANTIN | E34: 161.806 | F34: 9759 | G34: 60.53 | H34: 9903 | I34: 100 | J34: 0.706 | K34: 16.53 | L34: 76388436 | M34: 61353893 | N34: 33128.04
A35: Barra do Jacaré | B35: 4102703 | C35: barrense | D35: LUIZ FABIANO ZANATTA | E35: 115.855 | F35: 2814 | G35: 24.29 | H35: 2872 | I35: 100 | J35: 0.744 | K35: - | L35: 40385609 | M35: 32421151 | N35: 66502.51
A36: Bela Vista da Caroba | B36: 4102752 | C36: bela-vistense | D36: GELSON MAFFI | E36: 148.859 | F36: 4031 | G36: 27.22 | H36: 4122 | I36: 98.78 | J36: 0.681 | K36: - | L36: 41382475 | M36: 37302761 | N36: 31281.27
A37: Bela Vista do Paraíso | B37: 4102802 | C37: bela-vistense | D37: FABRICIO PASTORE | E37: 246.225 | F37: 14833 | G37: 61.12 | H37: 14982 | I37: 96.56 | J37: 0.716 | K37: 10.64 | L37: 1.1948572e+08 | M37: 1.0096663e+08 | N37: 38026.96
A38: Bituruna | B38: 4102901 | C38: biturenense | D38: RODRIGO ROSSONI | E38: 1280.76 | F38: 15533 | G38: 12.58 | H38: 15650 | I38: 98.35 | J38: 0.667 | K38: 7.72 | L38: 1.4071264e+08 | M38: 1.2695085e+08 | N38: 42256.96
A39: Boa Esperança | B39: 4103008 | C39: boa-esperansense | D39: JOEL CELSO BUSCARIOL | E39: 301.131 | F39: 4558 | G39: 15.06 | H39: 4595 | I39: 96.74 | J39: 0.72 | K39: 24.39 | L39: 71969832 | M39: 61581439 | N39: 75237.05
A40: Boa Esperança do Iguaçu | B40: 4103024 | C40: boaesperencense | D40: GIVANILDO TRUMI | E40: 152.252 | F40: 2455 | G40: 16.17 | H40: 2421 | I40: 100 | J40: 0.7 | K40: 34.48 | L40: 43954873 | M40: 38308780 | N40: 67222.53
A41: Boa Ventura de São Roque | B41: 4103040 | C41: boa venturense | D41: NESTOR KENEAR | E41: 606.94 | F41: 6378 | G41: 10.28 | H41: 6241 | I41: 99.8 | J41: 0.655 | K41: 11.76 | L41: 73000254 | M41: 64236260 | N41: 72838.58
...

Sheet  IPDM Indice Geral (IPARDES-PR)
A1: ÍNDICE IPARDES DE DESEMPENHO MUNICIPAL - PARANÁ - 2010/2022
A2: MUNICÍPIO | B2: ÍNDICE GERAL
B3: 2010 | C3: 2011 | D3: 2012 | E3: 2013 | F3: 2014 | G3: 2015 | H3: 2016 | I3: 2017 | J3: 2018 | K3: 2019 | L3: 2020 | M3: 2021 | N3: 2022
A4: Abatiá | B4: 0.564077 | C4: 0.54537785 | D4: 0.5168096 | E4: 0.53849931 | F4: 0.56491834 | G4: 0.63262387 | H4: 0.63228917 | I4: 0.63481531 | J4: 0.61980948 | K4: 0.65180705 | L4: 0.65156887 | M4: 0.69398485 | N4: 0.7555704
A5: Adrianópolis | B5: 0.44702252 | C5: 0.51774727 | D5: 0.54219822 | E5: 0.6240232 | F5: 0.61340338 | G5: 0.58026342 | H5: 0.59700793 | I5: 0.6884003 | J5: 0.69522748 | K5: 0.69379038 | L5: 0.67694205 | M5: 0.64804303 | N5: 0.69505186
A6: Agudos do Sul | B6: 0.41218907 | C6: 0.39040514 | D6: 0.38284435 | E6: 0.46841146 | F6: 0.54175781 | G6: 0.55755044 | H6: 0.55591232 | I6: 0.6134253 | J6: 0.59386109 | K6: 0.60161727 | L6: 0.59952608 | M6: 0.63719632 | N6: 0.614756
A7: Almirante Tamandaré | B7: 0.46560314 | C7: 0.50093557 | D7: 0.50554893 | E7: 0.52758322 | F7: 0.53124223 | G7: 0.53629596 | H7: 0.54938697 | I7: 0.59062928 | J7: 0.59288951 | K7: 0.63356937 | L7: 0.62274966 | M7: 0.62891539 | N7: 0.62592222
A8: Altamira do Paraná | B8: 0.52746038 | C8: 0.58325804 | D8: 0.56894039 | E8: 0.59070921 | F8: 0.57473214 | G8: 0.62996768 | H8: 0.63854211 | I8: 0.67205014 | J8: 0.69105158 | K8: 0.73973884 | L8: 0.75979605 | M8: 0.74667674 | N8: 0.7449448
A9: Alto Paraíso | B9: 0.51674093 | C9: 0.62090236 | D9: 0.60484247 | E9: 0.63757084 | F9: 0.59763252 | G9: 0.5909948 | H9: 0.65410728 | I9: 0.67611671 | J9: 0.71527441 | K9: 0.74971128 | L9: 0.73644605 | M9: 0.74074011 | N9: 0.75700085
A10: Alto Paraná | B10: 0.61542114 | C10: 0.62627205 | D10: 0.61529839 | E10: 0.61672566 | F10: 0.617619 | G10: 0.62168758 | H10: 0.64343372 | I10: 0.66109416 | J10: 0.67096147 | K10: 0.73346029 | L10: 0.72169885 | M10: 0.68193607 | N10: 0.68877462
A11: Alto Piquiri | B11: 0.6144691 | C11: 0.59431878 | D11: 0.53084762 | E11: 0.52566575 | F11: 0.54450521 | G11: 0.58269402 | H11: 0.60277442 | I11: 0.65212971 | J11: 0.6903576 | K11: 0.70697085 | L11: 0.68806261 | M11: 0.7071396 | N11: 0.71459995
A12: Altônia | B12: 0.68519693 | C12: 0.65989594 | D12: 0.64756916 | E12: 0.67217854 | F12: 0.65007854 | G12: 0.63564396 | H12: 0.61774078 | I12: 0.66157555 | J12: 0.68307556 | K12: 0.73828174 | L12: 0.73196724 | M12: 0.75810472 | N12: 0.7592004
A13: Alvorada do Sul | B13: 0.59633112 | C13: 0.60243452 | D13: 0.63656075 | E13: 0.61689733 | F13: 0.63142697 | G13: 0.61273772 | H13: 0.6500504 | I13: 0.68729565 | J13: 0.7050665 | K13: 0.71872591 | L13: 0.7288429 | M13: 0.69390252 | N13: 0.74697634
A14: Amaporã | B14: 0.55930688 | C14: 0.56543578 | D14: 0.5318201 | E14: 0.49453741 | F14: 0.50533953 | G14: 0.53852545 | H14: 0.55469994 | I14: 0.61917962 | J14: 0.62509943 | K14: 0.69859649 | L14: 0.72773861 | M14: 0.70616801 | N14: 0.71318269
A15: Ampére | B15: 0.61433147 | C15: 0.67044207 | D15: 0.66506949 | E15: 0.7133545 | F15: 0.70491885 | G15: 0.67233182 | H15: 0.65435023 | I15: 0.67765526 | J15: 0.73048227 | K15: 0.77922695 | L15: 0.79242883 | M15: 0.79009542 | N15: 0.8023288
