Workbook

Sheet Resumo Geral
A1: Painel DER — Liquidação Total: Exercício Corrente vs. RP / Exercício Anterior
A2: Elaborado a partir de: Empenhos 2024 CGM.xlsx, Anexo_1_ContratosDOPSR1 por Regional editável.xlsx e Pagamentos com RPs 2024-2025.xlsx (enviados pelo DER)
A4: Ano | B4: Liquidado Exercício Corrente (R$) | C4: Liquidado Total c/ RP (R$) | D4: RP / Exercício Anterior (R$) | E4: % RP sobre o Total Liquidado
A5: 2024 | B5: ='Resumo por Regional'!B10 -> 6.7705869e+08 | C5: ='Resumo por Regional'!C10 -> 6.8936345e+08 | D5: =C5-B5 -> 12304757 | E5: =D5/C5 -> 0.017849448
A6: 2025 | B6: ='Resumo por Regional'!F10 -> 8.2899734e+08 | C6: ='Resumo por Regional'!G10 -> 8.5536423e+08 | D6: =C6-B6 -> 26366890 | E6: =D6/C6 -> 0.030825336

Sheet Detalhe 2024
A1: Composição da Liquidação Total 2024 — Exercício Corrente vs. RP/Exercício Anterior
A2: Fonte (Exercício Corrente): Empenhos 2024 CGM.xlsx | Fonte (Total c/ RP): Pagamentos com RPs 2024-2025.xlsx (DER)
A4: Contrato | B4: Regional (SR) | C4: Tipo | D4: Liquidado Exercício Corrente (R$) | E4: Liquidado Total c/ RP (R$) | F4: RP / Exercício Anterior (R$) | G4: % RP sobre o Total | H4: Status | I4: Observação
A5: CO001/2023DOP | B5: Norte | C5: PROCONSERVA | E5: 0 | F5: =IF(H5="Casado",E5-D5,"") | G5: =IF(H5<>"Casado","",IF(E5=0,0,F5/E5)) | H5: Só na planilha c/ RP | I5: Não consta na base de exercício corrente — todo o valor liquidado pode ser RP/exercício anterior. Confirmar com DER.
A6: CO002/2023DOP | B6: Norte | C6: PROCONSERVA | E6: 248441.37 | F6: =IF(H6="Casado",E6-D6,"") | G6: =IF(H6<>"Casado","",IF(E6=0,0,F6/E6)) | H6: Só na planilha c/ RP | I6: Não consta na base de exercício corrente — todo o valor liquidado pode ser RP/exercício anterior. Confirmar com DER.
A7: CO004/2020DOP | B7: Noroeste | C7: COP | D7: 14155144 | E7: 14285872 | F7: =IF(H7="Casado",E7-D7,"") -> 130728.46 | G7: =IF(H7<>"Casado","",IF(E7=0,0,F7/E7)) -> 0.0091508909 | H7: Casado
A8: CO005/2020DOP | B8: Noroeste | C8: COP | D8: 10214286 | E8: 10214286 | F8: =IF(H8="Casado",E8-D8,"") -> 0 | G8: =IF(H8<>"Casado","",IF(E8=0,0,F8/E8)) -> 0 | H8: Casado
A9: CO006/2020DOP | B9: Norte | C9: COP | D9: 18480639 | E9: 18480639 | F9: =IF(H9="Casado",E9-D9,"") -> 0 | G9: =IF(H9<>"Casado","",IF(E9=0,0,F9/E9)) -> 0 | H9: Casado
A10: CO006/2023DOP | B10: Oeste | C10: PROCONSERVA | D10: 16776796 | E10: 18973723 | F10: =IF(H10="Casado",E10-D10,"") -> 2196926.3 | G10: =IF(H10<>"Casado","",IF(E10=0,0,F10/E10)) -> 0.11578784 | H10: Casado
A11: CO007/2020DOP | B11: Norte | C11: COP | D11: 12133453 | E11: 12133453 | F11: =IF(H11="Casado",E11-D11,"") -> 0 | G11: =IF(H11<>"Casado","",IF(E11=0,0,F11/E11)) -> 0 | H11: Casado
A12: CO007/2023DOP | B12: Oeste | C12: PROCONSERVA | D12: 10340245 | E12: 10340245 | F12: =IF(H12="Casado",E12-D12,"") -> 0 | G12: =IF(H12<>"Casado","",IF(E12=0,0,F12/E12)) -> 0 | H12: Casado
A13: CO009/2020DOP | B13: Noroeste | C13: COP | D13: 12411731 | E13: 12713728 | F13: =IF(H13="Casado",E13-D13,"") -> 301996.84 | G13: =IF(H13<>"Casado","",IF(E13=0,0,F13/E13)) -> 0.023753602 | H13: Casado
A14: CO015/2023DOP | B14: Noroeste | C14: PROCONSERVA | D14: 19306439 | E14: 19751606 | F14: =IF(H14="Casado",E14-D14,"") -> 445167.02 | G14: =IF(H14<>"Casado","",IF(E14=0,0,F14/E14)) -> 0.022538269 | H14: Casado
A15: CO016/2022DOP | B15: Campos Gerais | C15: PROCONSERVA | D15: 36705260 | E15: 36872432 | F15: =IF(H15="Casado",E15-D15,"") -> 167171.19 | G15: =IF(H15<>"Casado","",IF(E15=0,0,F15/E15)) -> 0.0045337718 | H15: Casado
A16: CO016/2023DOP | B16: Campos Gerais | C16: PROCONSERVA | D16: 31689339 | E16: 31689339 | F16: =IF(H16="Casado",E16-D16,"") -> 0 | G16: =IF(H16<>"Casado","",IF(E16=0,0,F16/E16)) -> 0 | H16: Casado
A17: CO017/2023DOP | B17: Oeste | C17: PROCONSERVA | D17: 19912516 | E17: 20054108 | F17: =IF(H17="Casado",E17-D17,"") -> 141592.29 | G17: =IF(H17<>"Casado","",IF(E17=0,0,F17/E17)) -> 0.007060513 | H17: Casado
A18: CO018/2023DOP | B18: Oeste | C18: PROCONSERVA | D18: 13351980 | E18: 13351980 | F18: =IF(H18="Casado",E18-D18,"") -> 0 | G18: =IF(H18<>"Casado","",IF(E18=0,0,F18/E18)) -> 0 | H18: Casado
... A33: CO059/2022DOP | B33: Leste | C33: PROCONSERVA | D33: 3493467.3 | E33: 5092825.8 | F33: =IF(H33="Casado",E33-D33,"") -> 1599358.6 | G33: =IF(H33<>"Casado","",IF(E33=0,0,F33/E33)) -> 0.31404148 | H33: Casado
A34: CO066/2018DOP | B34: Oeste | C34: COP | E34: 445521.88 | F34: =IF(H34="Casado",E34-D34,"") | G34: =IF(H34<>"Casado","",IF(E34=0,0,F34/E34)) | H34: Só na planilha c/ RP | I34: Não consta na base de exercício corrente — todo o valor liquidado pode ser RP/exercício anterior. Confirmar com DER.
A35: CO068/2018DOP | B35: Leste | C35: COP | E35: 385615.19 | F35: =IF(H35="Casado",E35-D35,"") | G35: =IF(H35<>"Casado","",IF(E35=0,0,F35/E35)) | H35: Só na planilha c/ RP | I35: Não consta na base de exercício corrente — todo o valor liquidado pode ser RP/exercício anterior. Confirmar com DER.
A36: CO069/2018DOP | B36: Oeste | C36: COP | E36: 22984.8 | F36: =IF(H36="Casado",E36-D36,"") | G36: =IF(H36<>"Casado","",IF(E36=0,0,F36/E36)) | H36: Só na planilha c/ RP | I36: Não consta na base de exercício corrente — todo o valor liquidado pode ser RP/exercício anterior. Confirmar com DER.
A37: CO069/2022DOP | B37: Noroeste | C37: PROCONSERVA | D37: 5132361.6 | E37: 5132361.6 | F37: =IF(H37="Casado",E37-D37,"") -> 0 | G37: =IF(H37<>"Casado","",IF(E37=0,0,F37/E37)) -> 0 | H37: Casado
A38: CO071/2023DOP | B38: Oeste | C38: PROCONSERVA | D38: 33555710 | E38: 37104577 | F38: =IF(H38="Casado",E38-D38,"") -> 3548866.9 | G38: =IF(H38<>"Casado","",IF(E38=0,0,F38/E38)) -> 0.095644991 | H38: Casado
A39: CO072/2022DOP | B39: Noroeste | C39: PROCONSERVA | D39: 6383091 | E39: 6439301.8 | F39: =IF(H39="Casado",E39-D39,"") -> 56210.84 | G39: =IF(H39<>"Casado","",IF(E39=0,0,F39/E39)) -> 0.0087293377 | H39: Casado
A40: CO089/2024DOP | B40: Norte | C40: INTEGRA | D40: 28994506 | E40: 28994506 | F40: =IF(H40="Casado",E40-D40,"") -> 0 | G40: =IF(H40<>"Casado","",IF(E40=0,0,F40/E40)) -> 0 | H40: Casado
A41: CO091/2024DOP | B41: Campos Gerais | C41: PROCONSERVA | D41: 15828848 | E41: 15828848 | F41: =IF(H41="Casado",E41-D41,"") -> 0 | G41: =IF(H41<>"Casado","",IF(E41=0,0,F41/E41)) -> 0 | H41: Casado
A42: CO093/2018DT-DOP | B42: Noroeste | C42: CREMEP | D42: 4809721.4 | E42: 5757152.6 | F42: =IF(H42="Casado",E42-D42,"") -> 947431.15 | G42: =IF(H42<>"Casado","",IF(E42=0,0,F42/E42)) -> 0.16456593 | H42: Casado
A43: CO123/2021DOP | B43: Noroeste | C43: PROCONSERVA | D43: 25933915 | E43: 25933915 | F43: =IF(H43="Casado",E43-D43,"") -> 0 | G43: =IF(H43<>"Casado","",IF(E43=0,0,F43/E43)) -> 0 | H43: Casado
A44: CO124/2021DOP | B44: Oeste | C44: PROCONSERVA | D44: 24493107 | E44: 24493107 | F44: =IF(H44="Casado",E44-D44,"") -> 0 | G44: =IF(H44<>"Casado","",IF(E44=0,0,F44/E44)) -> 0 | H44: Casado
A45: CO124/2024DOP | B45: Oeste | C45: PROCONSERVA | D45: 0 | E45: 0 | F45: =IF(H45="Casado",E45-D45,"") -> 0 | G45: =IF(H45<>"Casado","",IF(E45=0,0,F45/E45)) -> 0 | H45: Casado
A46: CO128/2021DOP | B46: Campos Gerais | C46: INTEGRA | D46: 12997591 | E46: 12997591 | F46: =IF(H46="Casado",E46-D46,"") -> 0 | G46: =IF(H46<>"Casado","",IF(E46=0,0,F46/E46)) -> 0 | H46: Casado
A47: CO129/2021DOP | B47: Norte | C47: INTEGRA | D47: 1271695.5 | E47: 1271695.5 | F47: =IF(H47="Casado",E47-D47,"") -> 0 | G47: =IF(H47<>"Casado","",IF(E47=0,0,F47/E47)) -> 0 | H47: Casado
A48: CO131/2021DOP | B48: Oeste | C48: INTEGRA | D48: 2669311.9 | E48: 2669311.9 | F48: =IF(H48="Casado",E48-D48,"") -> 0 | G48: =IF(H48<>"Casado","",IF(E48=0,0,F48/E48)) -> 0 | H48: Casado
A49: CO132/2021DOP | B49: Leste | C49: INTEGRA | D49: 2122955.6 | E49: 2378377.6 | F49: =IF(H49="Casado",E49-D49,"") -> 255422.03 | G49: =IF(H49<>"Casado","",IF(E49=0,0,F49/E49)) -> 0.10739339 | H49: Casado
A50: CO133/2021DOP | B50: Noroeste | C50: INTEGRA | E50: 12228615 | F50: =IF(H50="Casado",E50-D50,"") | G50: =IF(H50<>"Casado","",IF(E50=0,0,F50/E50)) | H50: Só na planilha c/ RP | I50: Não consta na base de exercício corrente — todo o valor liquidado pode ser RP/exercício anterior. Confirmar com DER.
A51: CO133/2021DOP | B51: Norte | C51: INTEGRA | D51: 10920913 | F51: =IF(H51="Casado",E51-D51,"") | G51: =IF(H51<>"Casado","",IF(E51=0,0,F51/E51)) | H51: Só na base (sem RP) | I51: Não consta na planilha com RP enviada pelo DER — confirmar se o contrato foi encerrado/reclassificado.
A52: CO142/2018DT-DOP | B52: Noroeste | C52: CREMEP | D52: 10186136 | E52: 10984857 | F52: =IF(H52="Casado",E52-D52,"") -> 798720.65 | G52: =IF(H52<>"Casado","",IF(E52=0,0,F52/E52)) -> 0.072711066 | H52: Casado
A53: CO167/2012DOP | B53: Oeste | C53: COP | E53: 558148.82 | F53: =IF(H53="Casado",E53-D53,"") | G53: =IF(H53<>"Casado","",IF(E53=0,0,F53/E53)) | H53: Só na planilha c/ RP | I53: Não consta na base de exercício corrente — todo o valor liquidado pode ser RP/exercício anterior. Confirmar com DER.
A54: CO169/2022DOP | B54: Campos Gerais | C54: PROCONSERVA | D54: 28953605 | E54: 28953605 | F54: =IF(H54="Casado",E54-D54,"") -> 0 | G54: =IF(H54<>"Casado","",IF(E54=0,0,F54/E54)) -> 0 | H54: Casado
A55: CO215/2012DOP | B55: Noroeste | C55: CREMEP | D55: 1600063.6 | E55: 1600063.6 | F55: =IF(H55="Casado",E55-D55,"") -> 0 | G55: =IF(H55<>"Casado","",IF(E55=0,0,F55/E55)) -> 0 | H55: Casado
...

Sheet Detalhe 2025
A1: Composição da Liquidação Total 2025 — Exercício Corrente vs. RP/Exercício Anterior
A2: Fonte (Exercício Corrente): Anexo_1_ContratosDOPSR1 por Regional editável.xlsx | Fonte (Total c/ RP): Pagamentos com RPs 2024-2025.xlsx (DER)
A4: Contrato | B4: Regional (SR) | C4: Tipo | D4: Liquidado Exercício Corrente (R$) | E4: Liquidado Total c/ RP (R$) | F4: RP / Exercício Anterior (R$) | G4: % RP sobre o Total | H4: Status | I4: Observação
A5: CO004/2020DOP | B5: Noroeste | C5: COP | D5: 39131336 | E5: 39631336 | F5: =IF(H5="Casado",E5-D5,"") -> 500000 | G5: =IF(H5<>"Casado","",IF(E5=0,0,F5/E5)) -> 0.012616279 | H5: Casado
A6: CO005/2020DOP | B6: Noroeste | C6: COP | D6: 4267004.2 | E6: 4767004.2 | F6: =IF(H6="Casado",E6-D6,"") -> 500000 | G6: =IF(H6<>"Casado","",IF(E6=0,0,F6/E6)) -> 0.10488768 | H6: Casado
A7: CO006/2020DOP | B7: Norte | C7: COP | D7: 32168827 | E7: 32168827 | F7: =IF(H7="Casado",E7-D7,"") -> 0 | G7: =IF(H7<>"Casado","",IF(E7=0,0,F7/E7)) -> 0 | H7: Casado
A8: CO006/2023DOP | B8: Oeste | C8: PROCONSERVA | D8: 26866862 | E8: 27666862 | F8: =IF(H8="Casado",E8-D8,"") -> 800000 | G8: =IF(H8<>"Casado","",IF(E8=0,0,F8/E8)) -> 0.028915459 | H8: Casado
A9: CO007/2020DOP | B9: Norte | C9: COP | D9: 20300896 | E9: 20351500 | F9: =IF(H9="Casado",E9-D9,"") -> 50604.37 | G9: =IF(H9<>"Casado","",IF(E9=0,0,F9/E9)) -> 0.0024865179 | H9: Casado
A10: CO007/2023DOP | B10: Oeste | C10: PROCONSERVA | D10: 8410678.3 | E10: 9210678.3 | F10: =IF(H10="Casado",E10-D10,"") -> 800000 | G10: =IF(H10<>"Casado","",IF(E10=0,0,F10/E10)) -> 0.08685571 | H10: Casado
A11: CO009/2020DOP | B11: Noroeste | C11: COP | D11: 34404476 | E11: 35004476 | F11: =IF(H11="Casado",E11-D11,"") -> 600000 | G11: =IF(H11<>"Casado","",IF(E11=0,0,F11/E11)) -> 0.017140665 | H11: Casado
A12: CO015/2023DOP | B12: Noroeste | C12: PROCONSERVA | D12: 70775631 | E12: 73002119 | F12: =IF(H12="Casado",E12-D12,"") -> 2226488.1 | G12: =IF(H12<>"Casado","",IF(E12=0,0,F12/E12)) -> 0.030498951 | H12: Casado
A13: CO016/2022DOP | B13: Campos Gerais | C13: PROCONSERVA | D13: 34514569 | E13: 35814569 | F13: =IF(H13="Casado",E13-D13,"") -> 1300000 | G13: =IF(H13<>"Casado","",IF(E13=0,0,F13/E13)) -> 0.036298078 | H13: Casado
A14: CO016/2023DOP | B14: Campos Gerais | C14: PROCONSERVA | D14: 30464840 | E14: 31264840 | F14: =IF(H14="Casado",E14-D14,"") -> 800000 | G14: =IF(H14<>"Casado","",IF(E14=0,0,F14/E14)) -> 0.025587849 | H14: Casado
A15: CO017/2023DOP | B15: Oeste | C15: PROCONSERVA | D15: 15748303 | E15: 16548303 | F15: =IF(H15="Casado",E15-D15,"") -> 800000 | G15: =IF(H15<>"Casado","",IF(E15=0,0,F15/E15)) -> 0.048343325 | H15: Casado
A16: CO018/2023DOP | B16: Oeste | C16: PROCONSERVA | D16: 193539.39 | E16: 193539.39 | F16: =IF(H16="Casado",E16-D16,"") -> 0 | G16: =IF(H16<>"Casado","",IF(E16=0,0,F16/E16)) -> 0 | H16: Casado
... A33: CO072/2025DOP | B33: Oeste | C33: PROCONSERVA | D33: 8642922.4 | E33: 8642922.4 | F33: =IF(H33="Casado",E33-D33,"") -> 0 | G33: =IF(H33<>"Casado","",IF(E33=0,0,F33/E33)) -> 0 | H33: Casado
A34: CO089/2024DOP | B34: Norte | C34: INTEGRA | D34: 23350268 | F34: =IF(H34="Casado",E34-D34,"") | G34: =IF(H34<>"Casado","",IF(E34=0,0,F34/E34)) | H34: Só na base (sem RP) | I34: Não consta na planilha com RP enviada pelo DER — confirmar se o contrato foi encerrado/reclassificado.
A35: CO091/2024DOP | B35: Campos Gerais | C35: PROCONSERVA | D35: 11123725 | E35: 11623725 | F35: =IF(H35="Casado",E35-D35,"") -> 500000 | G35: =IF(H35<>"Casado","",IF(E35=0,0,F35/E35)) -> 0.043015472 | H35: Casado
A36: CO092/2025DOP | B36: Oeste | C36: PROCONSERVA | D36: 21807371 | E36: 21807371 | F36: =IF(H36="Casado",E36-D36,"") -> 0 | G36: =IF(H36<>"Casado","",IF(E36=0,0,F36/E36)) -> 0 | H36: Casado
A37: CO093/2018DT-DOP | B37: Noroeste | C37: CREMEP | D37: 153364.94 | E37: 554929.91 | F37: =IF(H37="Casado",E37-D37,"") -> 401564.97 | G37: =IF(H37<>"Casado","",IF(E37=0,0,F37/E37)) -> 0.72363187 | H37: Casado
A38: CO121/2025DOP | B38: Oeste | C38: PROCONSERVA | D38: 13026376 | E38: 13026376 | F38: =IF(H38="Casado",E38-D38,"") -> 0 | G38: =IF(H38<>"Casado","",IF(E38=0,0,F38/E38)) -> 0 | H38: Casado
A39: CO123/2021DOP | B39: Noroeste | C39: PROCONSERVA | D39: 39138590 | E39: 39165738 | F39: =IF(H39="Casado",E39-D39,"") -> 27147.9 | G39: =IF(H39<>"Casado","",IF(E39=0,0,F39/E39)) -> 0.00069315431 | H39: Casado
A40: CO124/2021DOP | B40: Oeste | C40: PROCONSERVA | D40: 9243976 | E40: 10043976 | F40: =IF(H40="Casado",E40-D40,"") -> 800000 | G40: =IF(H40<>"Casado","",IF(E40=0,0,F40/E40)) -> 0.079649732 | H40: Casado
A41: CO124/2024DOP | B41: Oeste | C41: PROCONSERVA | D41: 31441685 | E41: 35751685 | F41: =IF(H41="Casado",E41-D41,"") -> 4310000 | G41: =IF(H41<>"Casado","",IF(E41=0,0,F41/E41)) -> 0.12055376 | H41: Casado
A42: CO128/2021DOP | B42: Campos Gerais | C42: INTEGRA | D42: 7285203.1 | F42: =IF(H42="Casado",E42-D42,"") | G42: =IF(H42<>"Casado","",IF(E42=0,0,F42/E42)) | H42: Só na base (sem RP) | I42: Não consta na planilha com RP enviada pelo DER — confirmar se o contrato foi encerrado/reclassificado.
A43: CO131/2021DOP | B43: Oeste | C43: INTEGRA | D43: 722042.87 | F43: =IF(H43="Casado",E43-D43,"") | G43: =IF(H43<>"Casado","",IF(E43=0,0,F43/E43)) | H43: Só na base (sem RP) | I43: Não consta na planilha com RP enviada pelo DER — confirmar se o contrato foi encerrado/reclassificado.
A44: CO133/2021DOP | B44: Norte | C44: INTEGRA | D44: 9182819.2 | F44: =IF(H44="Casado",E44-D44,"") | G44: =IF(H44<>"Casado","",IF(E44=0,0,F44/E44)) | H44: Só na base (sem RP) | I44: Não consta na planilha com RP enviada pelo DER — confirmar se o contrato foi encerrado/reclassificado.
A45: CO137/2025DOP | B45: Noroeste | C45: EMERGENCIAL | D45: 3173852.8 | E45: 3173852.8 | F45: =IF(H45="Casado",E45-D45,"") -> 0 | G45: =IF(H45<>"Casado","",IF(E45=0,0,F45/E45)) -> 0 | H45: Casado
A46: CO142/2018DT-DOP | B46: Noroeste | C46: CREMEP | D46: 2532160.2 | E46: 2557601.7 | F46: =IF(H46="Casado",E46-D46,"") -> 25441.54 | G46: =IF(H46<>"Casado","",IF(E46=0,0,F46/E46)) -> 0.0099474207 | H46: Casado
A47: CO152/2025DOP | B47: Noroeste | C47: EMERGENCIAL | D47: 923632.36 | E47: 923632.36 | F47: =IF(H47="Casado",E47-D47,"") -> 0 | G47: =IF(H47<>"Casado","",IF(E47=0,0,F47/E47)) -> 0 | H47: Casado
A48: CO169/2022DOP | B48: Campos Gerais | C48: PROCONSERVA | D48: 27448798 | E48: 28748798 | F48: =IF(H48="Casado",E48-D48,"") -> 1300000 | G48: =IF(H48<>"Casado","",IF(E48=0,0,F48/E48)) -> 0.045219282 | H48: Casado
A49: CO173/2025DOP | B49: Campos Gerais | C49: PROCONSERVA | D49: 8088945.3 | E49: 8088945.3 | F49: =IF(H49="Casado",E49-D49,"") -> 0 | G49: =IF(H49<>"Casado","",IF(E49=0,0,F49/E49)) -> 0 | H49: Casado
A50: CO175/2025DOP | B50: Campos Gerais | C50: PROCONSERVA | D50: 4181021.1 | E50: 4181021.1 | F50: =IF(H50="Casado",E50-D50,"") -> 0 | G50: =IF(H50<>"Casado","",IF(E50=0,0,F50/E50)) -> 0 | H50: Casado
A52: TOTAL — CONTRATOS CASADOS (usado no % RP) | D52: =SUMIFS(D5:D50,$H$5:$H$50,"Casado") -> 8.2899734e+08 | E52: =SUMIFS(E5:E50,$H$5:$H$50,"Casado") -> 8.5536423e+08 | F52: =SUMIFS(F5:F50,$H$5:$H$50,"Casado") -> 26366890 | G52: =F52/E52 -> 0.030825336
A53: Total — só na base (sem RP), não incluído no % RP acima | D53: =SUMIFS(D5:D50,$H$5:$H$50,"Só na base (sem RP)") -> 40540334
A54: Total — só na planilha c/ RP, não incluído no % RP acima | E54: =SUMIFS(E5:E50,$H$5:$H$50,"Só na planilha c/ RP") -> 0

Sheet Resumo por Regional
A1: Resumo por Regional — Liquidação: Exercício Corrente vs. RP/Exercício Anterior
A2: Considera apenas contratos casados entre as duas bases (ver Status nas abas de detalhe). Fórmulas SUMIFS.
A4: Regional | B4: Liquidado Exerc. Corrente 2024 (R$) | C4: Liquidado Total c/ RP 2024 (R$) | D4: RP 2024 (R$) | E4: % RP 2024 | F4: Liquidado Exerc. Corrente 2025 (R$) | G4: Liquidado Total c/ RP 2025 (R$) | H4: RP 2025 (R$) | I4: % RP 2025
A5: Campos Gerais | B5: =SUMIFS('Detalhe 2024'!D5:D57,'Detalhe 2024'!B5:B57,A5,'Detalhe 2024'!H5:H57,"Casado") -> 1.5732894e+08 | C5: =SUMIFS('Detalhe 2024'!E5:E57,'Detalhe 2024'!B5:B57,A5,'Detalhe 2024'!H5:H57,"Casado") -> 1.5749611e+08 | D5: =C5-B5 -> 167171.19 | E5: =IF(C5=0,"",D5/C5) -> 0.0010614306 | F5: =SUMIFS('Detalhe 2025'!D5:D50,'Detalhe 2025'!B5:B50,A5,'Detalhe 2025'!H5:H50,"Casado") -> 1.5475609e+08 | G5: =SUMIFS('Detalhe 2025'!E5:E50,'Detalhe 2025'!B5:B50,A5,'Detalhe 2025'!H5:H50,"Casado") -> 1.5865609e+08 | H5: =G5-F5 -> 3900000 | I5: =IF(G5=0,"",H5/G5) -> 0.02458147
A6: Leste | B6: =SUMIFS('Detalhe 2024'!D5:D57,'Detalhe 2024'!B5:B57,A6,'Detalhe 2024'!H5:H57,"Casado") -> 28609507 | C6: =SUMIFS('Detalhe 2024'!E5:E57,'Detalhe 2024'!B5:B57,A6,'Detalhe 2024'!H5:H57,"Casado") -> 31193779 | D6: =C6-B6 -> 2584271.6 | E6: =IF(C6=0,"",D6/C6) -> 0.082845738 | F6: =SUMIFS('Detalhe 2025'!D5:D50,'Detalhe 2025'!B5:B50,A6,'Detalhe 2025'!H5:H50,"Casado") -> 49640349 | G6: =SUMIFS('Detalhe 2025'!E5:E50,'Detalhe 2025'!B5:B50,A6,'Detalhe 2025'!H5:H50,"Casado") -> 50272276 | H6: =G6-F6 -> 631926.52 | I6: =IF(G6=0,"",H6/G6) -> 0.01257008
A7: Noroeste | B7: =SUMIFS('Detalhe 2024'!D5:D57,'Detalhe 2024'!B5:B57,A7,'Detalhe 2024'!H5:H57,"Casado") -> 1.3478335e+08 | C7: =SUMIFS('Detalhe 2024'!E5:E57,'Detalhe 2024'!B5:B57,A7,'Detalhe 2024'!H5:H57,"Casado") -> 1.3746361e+08 | D7: =C7-B7 -> 2680255 | E7: =IF(C7=0,"",D7/C7) -> 0.019497924 | F7: =SUMIFS('Detalhe 2025'!D5:D50,'Detalhe 2025'!B5:B50,A7,'Detalhe 2025'!H5:H50,"Casado") -> 1.993217e+08 | G7: =SUMIFS('Detalhe 2025'!E5:E50,'Detalhe 2025'!B5:B50,A7,'Detalhe 2025'!H5:H50,"Casado") -> 2.0410235e+08 | H7: =G7-F7 -> 4780642.5 | I7: =IF(G7=0,"",H7/G7) -> 0.023422771
A8: Norte | B8: =SUMIFS('Detalhe 2024'!D5:D57,'Detalhe 2024'!B5:B57,A8,'Detalhe 2024'!H5:H57,"Casado") -> 1.5180093e+08 | C8: =SUMIFS('Detalhe 2024'!E5:E57,'Detalhe 2024'!B5:B57,A8,'Detalhe 2024'!H5:H57,"Casado") -> 1.5180093e+08 | D8: =C8-B8 -> 0 | E8: =IF(C8=0,"",D8/C8) -> 0 | F8: =SUMIFS('Detalhe 2025'!D5:D50,'Detalhe 2025'!B5:B50,A8,'Detalhe 2025'!H5:H50,"Casado") -> 1.8665121e+08 | G8: =SUMIFS('Detalhe 2025'!E5:E50,'Detalhe 2025'!B5:B50,A8,'Detalhe 2025'!H5:H50,"Casado") -> 1.9137959e+08 | H8: =G8-F8 -> 4728375.9 | I8: =IF(G8=0,"",H8/G8) -> 0.024706793
A9: Oeste | B9: =SUMIFS('Detalhe 2024'!D5:D57,'Detalhe 2024'!B5:B57,A9,'Detalhe 2024'!H5:H57,"Casado") -> 2.0453597e+08 | C9: =SUMIFS('Detalhe 2024'!E5:E57,'Detalhe 2024'!B5:B57,A9,'Detalhe 2024'!H5:H57,"Casado") -> 2.1140903e+08 | D9: =C9-B9 -> 6873059.6 | E9: =IF(C9=0,"",D9/C9) -> 0.032510719 | F9: =SUMIFS('Detalhe 2025'!D5:D50,'Detalhe 2025'!B5:B50,A9,'Detalhe 2025'!H5:H50,"Casado") -> 2.3862799e+08 | G9: =SUMIFS('Detalhe 2025'!E5:E50,'Detalhe 2025'!B5:B50,A9,'Detalhe 2025'!H5:H50,"Casado") -> 2.5095393e+08 | H9: =G9-F9 -> 12325945 | I9: =IF(G9=0,"",H9/G9) -> 0.049116366
A10: TOTAL GERAL | B10: =SUM(B5:B9) -> 6.7705869e+08 | C10: =SUM(C5:C9) -> 6.8936345e+08 | D10: =SUM(D5:D9) -> 12304757 | E10: =D10/C10 -> 0.017849448 | F10: =SUM(F5:F9) -> 8.2899734e+08 | G10: =SUM(G5:G9) -> 8.5536423e+08 | H10: =SUM(H5:H9) -> 26366890 | I10: =H10/G10 -> 0.030825336
